Workbook

Sheet ReadMe
A1: Do NOT edit any formulas in the highligted columns, it will mess up the mapping. Only drag them down. Orange highlight means manually added (don't drag down).
A2: Final Tab | B2: The final tab is what is read into the dashboard as the CalSim to WEAP map. It uses a combination of all variables from the dashboard (historical and planning FV files) - unfilter it to see all of them. Common name mapping is also planned to be added. This tab shouldn't be edited. Orange highlighted rows are duplicate CalSim variables (either in both SacWAM and SJWAM or duplicated in the mapping tab) - rows are copied from the Duplicated tab (hidden).
A6: Mapping Tab | B6: The non-highlighted columns come from Sac and SJWAM post-processors which mapped CalSim to WEAP variables. Add more mapping/rows as needed and drag down the highlighted column's formulas. Evaporation, applied water demand, and groundwater pumping variables were manually mapped (highlighted in orange). AW and GP variables were mapped by DU using the DU Map tab (hidden).
A10: WEAP Tab | B10: The non-highlighted columns are what are exported from the WEAP model favorites (Sac and SJWAM). If new favorites are added, you will need to export the data and add it, then drag down the highlighted column's formulas. Use the scripts in the input_files/WEAP_CalSim folder. Export the units in the equivalent CalSim variable's units. Calculated variables or data without an ObjID are given a synthetic ObjID of -999 and may need to be updated in the code.
A14: WEAP Favorites Tab | B14: This tab instructs what favorites to set in WEAP and what to call them (don't add the favorites to a folder). I exported everything in TAF. Update these as needed (and add the variables to the WEAP tab). Only the CSVs listed in the CSV File column are what are used to create the final CalSim-formatted CSV which goes into the data folder and onto the dashboard. Red text means the favorite name is different than the default. Green highlighted ones are added, while red should be in the future (unfilter the CSV File column).
A20: A note on how the mapping works:
A21: "Match Key" ignores the number before the \ (unless it is a reach)
A22: "Match Var" only looks at the number before the \ and anything following after (unless it is a headflow or reach)
A23: First, it tries to match the "Match Key" in the WEAP and Mapping tabs, then if there is still no match, it looks at the "Match Var"
A24: Reasoning and dashboard logic:
A25: The numbers before the \ change between models when anything is added or changed. It is assumed the ObjID does not change, but can be duplicated for different favorites.
A26: For data without a -999 ObjID, the dashboard merges on the ObjID and WEAP Favorite to convert to CalSim format.
A27: Data with a -999 ObjID merge on the WEAP Variable and WEAP Favorite.

Sheet Final
A1: CalSim Variable | B1: CalSim Kind | C1: ObjID | D1: WEAP Variable | E1: WEAP Model | F1: WEAP Favorite
A2: SWP_PERCENT_ACT | B2: ALIAS | C2: =_xlfn.XLOOKUP($A2,Mapping!$A:$A,Mapping!$D:$D) -> #N/A | D2: =_xlfn.XLOOKUP($A2,Mapping!$A:$A,Mapping!$E:$E) -> #N/A | E2: =_xlfn.XLOOKUP($A2,Mapping!$A:$A,Mapping!$C:$C) -> #N/A | F2: =_xlfn.XLOOKUP($A2,Mapping!$A:$A,Mapping!$G:$G) -> #N/A
A3: AW_02_NA | B3: APPLIED-WATER | C3: =_xlfn.XLOOKUP($A3,Mapping!$A:$A,Mapping!$D:$D) -> -999 | D3: =_xlfn.XLOOKUP($A3,Mapping!$A:$A,Mapping!$E:$E) -> A_02_NA | E3: =_xlfn.XLOOKUP($A3,Mapping!$A:$A,Mapping!$C:$C) -> SacWAM | F3: =_xlfn.XLOOKUP($A3,Mapping!$A:$A,Mapping!$G:$G) -> Theoretical Catchment Irrigation Demand
A4: AW_02_PA | B4: APPLIED-WATER | C4: =_xlfn.XLOOKUP($A4,Mapping!$A:$A,Mapping!$D:$D) -> -999 | D4: =_xlfn.XLOOKUP($A4,Mapping!$A:$A,Mapping!$E:$E) -> A_02_PA | E4: =_xlfn.XLOOKUP($A4,Mapping!$A:$A,Mapping!$C:$C) -> SacWAM | F4: =_xlfn.XLOOKUP($A4,Mapping!$A:$A,Mapping!$G:$G) -> Theoretical Catchment Irrigation Demand
A5: AW_02_SA | B5: APPLIED-WATER | C5: =_xlfn.XLOOKUP($A5,Mapping!$A:$A,Mapping!$D:$D) -> -999 | D5: =_xlfn.XLOOKUP($A5,Mapping!$A:$A,Mapping!$E:$E) -> A_02_SA | E5: =_xlfn.XLOOKUP($A5,Mapping!$A:$A,Mapping!$C:$C) -> SacWAM | F5: =_xlfn.XLOOKUP($A5,Mapping!$A:$A,Mapping!$G:$G) -> Theoretical Catchment Irrigation Demand
A6: AW_03_NA | B6: APPLIED-WATER | C6: =_xlfn.XLOOKUP($A6,Mapping!$A:$A,Mapping!$D:$D) -> -999 | D6: =_xlfn.XLOOKUP($A6,Mapping!$A:$A,Mapping!$E:$E) -> A_03_NA | E6: =_xlfn.XLOOKUP($A6,Mapping!$A:$A,Mapping!$C:$C) -> SacWAM | F6: =_xlfn.XLOOKUP($A6,Mapping!$A:$A,Mapping!$G:$G) -> Theoretical Catchment Irrigation Demand
A7: AW_03_PA | B7: APPLIED-WATER | C7: =_xlfn.XLOOKUP($A7,Mapping!$A:$A,Mapping!$D:$D) -> -999 | D7: =_xlfn.XLOOKUP($A7,Mapping!$A:$A,Mapping!$E:$E) -> A_03_PA | E7: =_xlfn.XLOOKUP($A7,Mapping!$A:$A,Mapping!$C:$C) -> SacWAM | F7: =_xlfn.XLOOKUP($A7,Mapping!$A:$A,Mapping!$G:$G) -> Theoretical Catchment Irrigation Demand
A8: AW_03_SA | B8: APPLIED-WATER | C8: =_xlfn.XLOOKUP($A8,Mapping!$A:$A,Mapping!$D:$D) -> -999 | D8: =_xlfn.XLOOKUP($A8,Mapping!$A:$A,Mapping!$E:$E) -> A_03_SA | E8: =_xlfn.XLOOKUP($A8,Mapping!$A:$A,Mapping!$C:$C) -> SacWAM | F8: =_xlfn.XLOOKUP($A8,Mapping!$A:$A,Mapping!$G:$G) -> Theoretical Catchment Irrigation Demand
A9: AW_04_NA | B9: APPLIED-WATER | C9: =_xlfn.XLOOKUP($A9,Mapping!$A:$A,Mapping!$D:$D) -> -999 | D9: =_xlfn.XLOOKUP($A9,Mapping!$A:$A,Mapping!$E:$E) -> A_04_06_NA2 | E9: =_xlfn.XLOOKUP($A9,Mapping!$A:$A,Mapping!$C:$C) -> SacWAM | F9: =_xlfn.XLOOKUP($A9,Mapping!$A:$A,Mapping!$G:$G) -> Theoretical Catchment Irrigation Demand
A10: AW_04_PA1 | B10: APPLIED-WATER | C10: =_xlfn.XLOOKUP($A10,Mapping!$A:$A,Mapping!$D:$D) -> -999 | D10: =_xlfn.XLOOKUP($A10,Mapping!$A:$A,Mapping!$E:$E) -> A_04_06_PA1 | E10: =_xlfn.XLOOKUP($A10,Mapping!$A:$A,Mapping!$C:$C) -> SacWAM | F10: =_xlfn.XLOOKUP($A10,Mapping!$A:$A,Mapping!$G:$G) -> Theoretical Catchment Irrigation Demand
A11: AW_04_PA2 | B11: APPLIED-WATER | C11: =_xlfn.XLOOKUP($A11,Mapping!$A:$A,Mapping!$D:$D) -> -999 | D11: =_xlfn.XLOOKUP($A11,Mapping!$A:$A,Mapping!$E:$E) -> A_04_06_PA2 | E11: =_xlfn.XLOOKUP($A11,Mapping!$A:$A,Mapping!$C:$C) -> SacWAM | F11: =_xlfn.XLOOKUP($A11,Mapping!$A:$A,Mapping!$G:$G) -> Theoretical Catchment Irrigation Demand
A12: AW_05_NA | B12: APPLIED-WATER | C12: =_xlfn.XLOOKUP($A12,Mapping!$A:$A,Mapping!$D:$D) -> -999 | D12: =_xlfn.XLOOKUP($A12,Mapping!$A:$A,Mapping!$E:$E) -> A_05_NA | E12: =_xlfn.XLOOKUP($A12,Mapping!$A:$A,Mapping!$C:$C) -> SacWAM | F12: =_xlfn.XLOOKUP($A12,Mapping!$A:$A,Mapping!$G:$G) -> Theoretical Catchment Irrigation Demand
A13: AW_06_NA | B13: APPLIED-WATER | C13: =_xlfn.XLOOKUP($A13,Mapping!$A:$A,Mapping!$D:$D) -> #N/A | D13: =_xlfn.XLOOKUP($A13,Mapping!$A:$A,Mapping!$E:$E) -> #N/A | E13: =_xlfn.XLOOKUP($A13,Mapping!$A:$A,Mapping!$C:$C) -> #N/A | F13: =_xlfn.XLOOKUP($A13,Mapping!$A:$A,Mapping!$G:$G) -> #N/A
... A618: C_CFS001 | B618: CHANNEL | C618: =_xlfn.XLOOKUP($A618,Mapping!$A:$A,Mapping!$D:$D) | D618: =_xlfn.XLOOKUP($A618,Mapping!$A:$A,Mapping!$E:$E) | E618: =_xlfn.XLOOKUP($A618,Mapping!$A:$A,Mapping!$C:$C) -> SJWAM | F618: =_xlfn.XLOOKUP($A618,Mapping!$A:$A,Mapping!$G:$G)
A619: C_MFT011 | B619: CHANNEL | C619: 14306 | D619: Hell Hole Tunnel 0 \ Headflow | E619: SacWAM | F619: Streamflow (below node or reach listed) | G619: Duplicate
A620: C_CMN006 | B620: CHANNEL | C620: 13975 | D620: Camino Conduit 0 \ Headflow | E620: SacWAM | F620: Streamflow (below node or reach listed) | G620: Duplicate
A621: C_CAA003 | B621: CHANNEL | C621: 6638 | D621: California Aqueduct 0 \ Headflow | E621: SacWAM | F621: Streamflow (below node or reach listed) | G621: Duplicate
A622: C_NFA022 | B622: CHANNEL | C622: 6643 | D622: North Fork American River 15 \ I_NFA022 Inflow | E622: SacWAM | F622: Streamflow (below node or reach listed) | G622: Duplicate
A623: C_SFA030 | B623: CHANNEL | C623: 6170 | D623: South Fork American River 47 \ SF American nr Placerville | E623: SacWAM | F623: Streamflow (below node or reach listed) | G623: Duplicate
A624: C_BRR066 | B624: CHANNEL | C624: 10942 | D624: Bear River 5 \ Drum Afterbay | E624: SacWAM | F624: Streamflow (below node or reach listed) | G624: Duplicate
A625: C_TTC002 | B625: CHANNEL | C625: 5019 | D625: Toadtown Canal 0 \ Headflow | E625: SacWAM | F625: Streamflow (below node or reach listed) | G625: Duplicate
A626: C_TAB000 | B626: CHANNEL | C626: 4427 | D626: Power Canal 7 \ Thermalito Afterbay | E626: SacWAM | F626: Streamflow (below node or reach listed) | G626: Duplicate
A627: C_BTL006 | B627: CHANNEL | C627: 12490 | D627: Battle Creek 11 \ SWRCB Battle Creek | E627: SacWAM | F627: Streamflow (below node or reach listed) | G627: Duplicate
A628: C_PYN001 | B628: CHANNEL | C628: 5821 | D628: Paynes Creek 5 \ I_PYN001 Inflow | E628: SacWAM | F628: Streamflow (below node or reach listed) | G628: Duplicate
A629: C_SJR070 | B629: CHANNEL | C629: 9267 | D629: San Joaquin River 1 \ Inflow at Vernalis Inflow | E629: SacWAM | F629: Streamflow (below node or reach listed) | G629: Duplicate
A630: C_MOK034 | B630: CHANNEL | C630: 12533 | D630: Mokelumne River 43 \ SWRCB Mokelumne River | E630: SacWAM | F630: Streamflow (below node or reach listed) | G630: Duplicate
... A648: C_EBP042 | B648: CHANNEL | C648: 15237 | D648: Eastside Bypass 41 \ Deadman Creek Inflow | E648: SJWAM | F648: Streamflow (below node or reach listed) | G648: Duplicate
A649: C_FCS006 | B649: CHANNEL | E649: SJWAM | G649: Duplicate
A650: C_EBP033 | B650: CHANNEL | E650: SJWAM | G650: Duplicate
A651: C_CAA003 | B651: CHANNEL | C651: 21633 | D651: California Aqueduct 3 \ Withdrawal Node 44 | E651: SJWAM | F651: Streamflow (below node or reach listed) | G651: Duplicate
A652: C_EBP050 | B652: CHANNEL | E652: SJWAM | G652: Duplicate
A653: C_DMC003 | B653: CHANNEL | C653: 16811 | D653: Delta Mendota Canal 1 \ CVP Boundary Condition | E653: SJWAM | F653: Streamflow (below node or reach listed) | G653: Duplicate
A654: C_SLUIS_CVP | B654: CHANNEL | E654: SJWAM | G654: Duplicate
A655: C_CVT009 | B655: CHANNEL | C655: 19423 | D655: Collierville Tunnel 3 \ OPS Collierville Tunnel | E655: SJWAM | F655: Streamflow (below node or reach listed) | G655: Duplicate
A656: SG128_ORT014_19 | B656: CHANNEL-SEEPAGE | C656: =_xlfn.XLOOKUP($A656,Mapping!$A:$A,Mapping!$D:$D) -> #N/A | D656: =_xlfn.XLOOKUP($A656,Mapping!$A:$A,Mapping!$E:$E) -> #N/A | E656: =_xlfn.XLOOKUP($A656,Mapping!$A:$A,Mapping!$C:$C) -> #N/A | F656: =_xlfn.XLOOKUP($A656,Mapping!$A:$A,Mapping!$G:$G) -> #N/A
A657: SG129_ORT009_19 | B657: CHANNEL-SEEPAGE | C657: =_xlfn.XLOOKUP($A657,Mapping!$A:$A,Mapping!$D:$D) -> #N/A | D657: =_xlfn.XLOOKUP($A657,Mapping!$A:$A,Mapping!$E:$E) -> #N/A | E657: =_xlfn.XLOOKUP($A657,Mapping!$A:$A,Mapping!$C:$C) -> #N/A | F657: =_xlfn.XLOOKUP($A657,Mapping!$A:$A,Mapping!$G:$G) -> #N/A
A658: SG130_ORT001_19 | B658: CHANNEL-SEEPAGE | C658: =_xlfn.XLOOKUP($A658,Mapping!$A:$A,Mapping!$D:$D) -> #N/A | D658: =_xlfn.XLOOKUP($A658,Mapping!$A:$A,Mapping!$E:$E) -> #N/A | E658: =_xlfn.XLOOKUP($A658,Mapping!$A:$A,Mapping!$C:$C) -> #N/A | F658: =_xlfn.XLOOKUP($A658,Mapping!$A:$A,Mapping!$G:$G) -> #N/A
A659: SG51_FSL012_4 | B659: CHANNEL-SEEPAGE | C659: =_xlfn.XLOOKUP($A659,Mapping!$A:$A,Mapping!$D:$D) -> #N/A | D659: =_xlfn.XLOOKUP($A659,Mapping!$A:$A,Mapping!$E:$E) -> #N/A | E659: =_xlfn.XLOOKUP($A659,Mapping!$A:$A,Mapping!$C:$C) -> #N/A | F659: =_xlfn.XLOOKUP($A659,Mapping!$A:$A,Mapping!$G:$G) -> #N/A
A660: SG52_FSL005_4 | B660: CHANNEL-SEEPAGE | C660: =_xlfn.XLOOKUP($A660,Mapping!$A:$A,Mapping!$D:$D) -> #N/A | D660: =_xlfn.XLOOKUP($A660,Mapping!$A:$A,Mapping!$E:$E) -> #N/A | E660: =_xlfn.XLOOKUP($A660,Mapping!$A:$A,Mapping!$C:$C) -> #N/A | F660: =_xlfn.XLOOKUP($A660,Mapping!$A:$A,Mapping!$G:$G) -> #N/A
A661: SG53_FSL005_4 | B661: CHANNEL-SEEPAGE | C661: =_xlfn.XLOOKUP($A661,Mapping!$A:$A,Mapping!$D:$D) -> #N/A | D661: =_xlfn.XLOOKUP($A661,Mapping!$A:$A,Mapping!$E:$E) -> #N/A | E661: =_xlfn.XLOOKUP($A661,Mapping!$A:$A,Mapping!$C:$C) -> #N/A | F661: =_xlfn.XLOOKUP($A661,Mapping!$A:$A,Mapping!$G:$G) -> #N/A
...

Sheet Mapping
A1: CalSim Variable | B1: WEAP Variable | C1: WEAP Model | D1: ObjID | E1: WEAP Variable | F1: WEAP Units | G1: WEAP Favorite | H1: Match Key | I1: Match Var
A2: Trinity River at Lewiston | B2: Trinity River at Lewiston | C2: SacWAM | D2: =IFERROR( _xlfn.XLOOKUP($H2,WEAP!$F:$F,WEAP!$A:$A), IF($I2="","",_xlfn.XLOOKUP($I2,WEAP!$G:$G,WEAP!$A:$A,"")) ) | E2: =IFERROR( _xlfn.XLOOKUP($H2,WEAP!$F:$F,WEAP!$B:$B), IF($I2="","",_xlfn.XLOOKUP($I2,WEAP!$G:$G,WEAP!$B:$B,"")) ) | F2: =IFERROR( _xlfn.XLOOKUP($H2,WEAP!$F:$F,WEAP!$C:$C), IF($I2="","",_xlfn.XLOOKUP($I2,WEAP!$G:$G,WEAP!$C:$C,"")) ) | G2: =IFERROR( _xlfn.XLOOKUP($H2,WEAP!$F:$F,WEAP!$E:$E), IF($I2="","",_xlfn.XLOOKUP($I2,WEAP!$G:$G,WEAP!$E:$E,"")) ) | H2: =IFERROR( _xlfn.LET( _xlpm.txt,TRIM(B2), _xlpm.before,TRIM(_xlfn.TEXTBEFORE(_xlpm.txt,"\",-1)), _xlpm.after,_xlfn.TEXTAFTER(_xlpm.txt,"\"), _xlpm.lastToken,TRIM(_xlfn.TEXTAFTER(_xlpm.before," ",-1)), _xlpm.isReach,LOWER(TRIM(_xlpm.after))="reach", _xlpm.cleaned, IF( ISNUMBER(--_xlpm.lastToken), _xlfn.TEXTBEFORE(_xlpm.before," ",-1) & " \ " & _xlpm.after, _xlpm.txt ), IF(_xlpm.isReach,_xlpm.txt,TRIM(_xlpm.cleaned)) ), B2 ) -> Trinity River at Lewiston | I2: =IFERROR( _xlfn.LET( _xlpm.txt,B2, _xlpm.before,TRIM(_xlfn.TEXTBEFORE(_xlpm.txt,"\")), _xlpm.after,TRIM(_xlfn.TEXTAFTER(_xlpm.txt,"\")), _xlpm.lastToken,TRIM(_xlfn.TEXTAFTER(_xlpm.before," ",-1)), _xlpm.isNum,IFERROR(ISNUMBER(--_xlpm.lastToken),FALSE), IF( OR( LOWER(_xlpm.after)="headflow", LOWER(_xlpm.after)="reach" ), "", IF( _xlpm.isNum, _xlpm.lastToken & " \ " & _xlpm.after, "" ) ) ), "" )
A3: Sacramento River at Shasta | B3: Sacramento River at Shasta | C3: SacWAM | D3: =IFERROR( _xlfn.XLOOKUP($H3,WEAP!$F:$F,WEAP!$A:$A), IF($I3="","",_xlfn.XLOOKUP($I3,WEAP!$G:$G,WEAP!$A:$A,"")) ) | E3: =IFERROR( _xlfn.XLOOKUP($H3,WEAP!$F:$F,WEAP!$B:$B), IF($I3="","",_xlfn.XLOOKUP($I3,WEAP!$G:$G,WEAP!$B:$B,"")) ) | F3: =IFERROR( _xlfn.XLOOKUP($H3,WEAP!$F:$F,WEAP!$C:$C), IF($I3="","",_xlfn.XLOOKUP($I3,WEAP!$G:$G,WEAP!$C:$C,"")) ) | G3: =IFERROR( _xlfn.XLOOKUP($H3,WEAP!$F:$F,WEAP!$E:$E), IF($I3="","",_xlfn.XLOOKUP($I3,WEAP!$G:$G,WEAP!$E:$E,"")) ) | H3: =IFERROR( _xlfn.LET( _xlpm.txt,TRIM(B3), _xlpm.before,TRIM(_xlfn.TEXTBEFORE(_xlpm.txt,"\",-1)), _xlpm.after,_xlfn.TEXTAFTER(_xlpm.txt,"\"), _xlpm.lastToken,TRIM(_xlfn.TEXTAFTER(_xlpm.before," ",-1)), _xlpm.isReach,LOWER(TRIM(_xlpm.after))="reach", _xlpm.cleaned, IF( ISNUMBER(--_xlpm.lastToken), _xlfn.TEXTBEFORE(_xlpm.before," ",-1) & " \ " & _xlpm.after, _xlpm.txt ), IF(_xlpm.isReach,_xlpm.txt,TRIM(_xlpm.cleaned)) ), B3 ) -> Sacramento River at Shasta | I3: =IFERROR( _xlfn.LET( _xlpm.txt,B3, _xlpm.before,TRIM(_xlfn.TEXTBEFORE(_xlpm.txt,"\")), _xlpm.after,TRIM(_xlfn.TEXTAFTER(_xlpm.txt,"\")), _xlpm.lastToken,TRIM(_xlfn.TEXTAFTER(_xlpm.before," ",-1)), _xlpm.isNum,IFERROR(ISNUMBER(--_xlpm.lastToken),FALSE), IF( OR( LOWER(_xlpm.after)="headflow", LOWER(_xlpm.after)="reach" ), "", IF( _xlpm.isNum, _xlpm.lastToken & " \ " & _xlpm.after, "" ) ) ), "" )
A4: Feather River at Oroville | B4: Feather River at Oroville | C4: SacWAM | D4: =IFERROR( _xlfn.XLOOKUP($H4,WEAP!$F:$F,WEAP!$A:$A), IF($I4="","",_xlfn.XLOOKUP($I4,WEAP!$G:$G,WEAP!$A:$A,"")) ) | E4: =IFERROR( _xlfn.XLOOKUP($H4,WEAP!$F:$F,WEAP!$B:$B), IF($I4="","",_xlfn.XLOOKUP($I4,WEAP!$G:$G,WEAP!$B:$B,"")) ) | F4: =IFERROR( _xlfn.XLOOKUP($H4,WEAP!$F:$F,WEAP!$C:$C), IF($I4="","",_xlfn.XLOOKUP($I4,WEAP!$G:$G,WEAP!$C:$C,"")) ) | G4: =IFERROR( _xlfn.XLOOKUP($H4,WEAP!$F:$F,WEAP!$E:$E), IF($I4="","",_xlfn.XLOOKUP($I4,WEAP!$G:$G,WEAP!$E:$E,"")) ) | H4: =IFERROR( _xlfn.LET( _xlpm.txt,TRIM(B4), _xlpm.before,TRIM(_xlfn.TEXTBEFORE(_xlpm.txt,"\",-1)), _xlpm.after,_xlfn.TEXTAFTER(_xlpm.txt,"\"), _xlpm.lastToken,TRIM(_xlfn.TEXTAFTER(_xlpm.before," ",-1)), _xlpm.isReach,LOWER(TRIM(_xlpm.after))="reach", _xlpm.cleaned, IF( ISNUMBER(--_xlpm.lastToken), _xlfn.TEXTBEFORE(_xlpm.before," ",-1) & " \ " & _xlpm.after, _xlpm.txt ), IF(_xlpm.isReach,_xlpm.txt,TRIM(_xlpm.cleaned)) ), B4 ) -> Feather River at Oroville | I4: =IFERROR( _xlfn.LET( _xlpm.txt,B4, _xlpm.before,TRIM(_xlfn.TEXTBEFORE(_xlpm.txt,"\")), _xlpm.after,TRIM(_xlfn.TEXTAFTER(_xlpm.txt,"\")), _xlpm.lastToken,TRIM(_xlfn.TEXTAFTER(_xlpm.before," ",-1)), _xlpm.isNum,IFERROR(ISNUMBER(--_xlpm.lastToken),FALSE), IF( OR( LOWER(_xlpm.after)="headflow", LOWER(_xlpm.after)="reach" ), "", IF( _xlpm.isNum, _xlpm.lastToken & " \ " & _xlpm.after, "" ) ) ), "" )
A5: Yuba River above Daguerre | B5: Yuba River above Daguerre | C5: SacWAM | D5: =IFERROR( _xlfn.XLOOKUP($H5,WEAP!$F:$F,WEAP!$A:$A), IF($I5="","",_xlfn.XLOOKUP($I5,WEAP!$G:$G,WEAP!$A:$A,"")) ) | E5: =IFERROR( _xlfn.XLOOKUP($H5,WEAP!$F:$F,WEAP!$B:$B), IF($I5="","",_xlfn.XLOOKUP($I5,WEAP!$G:$G,WEAP!$B:$B,"")) ) | F5: =IFERROR( _xlfn.XLOOKUP($H5,WEAP!$F:$F,WEAP!$C:$C), IF($I5="","",_xlfn.XLOOKUP($I5,WEAP!$G:$G,WEAP!$C:$C,"")) ) | G5: =IFERROR( _xlfn.XLOOKUP($H5,WEAP!$F:$F,WEAP!$E:$E), IF($I5="","",_xlfn.XLOOKUP($I5,WEAP!$G:$G,WEAP!$E:$E,"")) ) | H5: =IFERROR( _xlfn.LET( _xlpm.txt,TRIM(B5), _xlpm.before,TRIM(_xlfn.TEXTBEFORE(_xlpm.txt,"\",-1)), _xlpm.after,_xlfn.TEXTAFTER(_xlpm.txt,"\"), _xlpm.lastToken,TRIM(_xlfn.TEXTAFTER(_xlpm.before," ",-1)), _xlpm.isReach,LOWER(TRIM(_xlpm.after))="reach", _xlpm.cleaned, IF( ISNUMBER(--_xlpm.lastToken), _xlfn.TEXTBEFORE(_xlpm.before," ",-1) & " \ " & _xlpm.after, _xlpm.txt ), IF(_xlpm.isReach,_xlpm.txt,TRIM(_xlpm.cleaned)) ), B5 ) -> Yuba River above Daguerre | I5: =IFERROR( _xlfn.LET( _xlpm.txt,B5, _xlpm.before,TRIM(_xlfn.TEXTBEFORE(_xlpm.txt,"\")), _xlpm.after,TRIM(_xlfn.TEXTAFTER(_xlpm.txt,"\")), _xlpm.lastToken,TRIM(_xlfn.TEXTAFTER(_xlpm.before," ",-1)), _xlpm.isNum,IFERROR(ISNUMBER(--_xlpm.lastToken),FALSE), IF( OR( LOWER(_xlpm.after)="headflow", LOWER(_xlpm.after)="reach" ), "", IF( _xlpm.isNum, _xlpm.lastToken & " \ " & _xlpm.after, "" ) ) ), "" )
A6: Bear River at Camp Far West | B6: Bear River at Camp Far West | C6: SacWAM | D6: =IFERROR( _xlfn.XLOOKUP($H6,WEAP!$F:$F,WEAP!$A:$A), IF($I6="","",_xlfn.XLOOKUP($I6,WEAP!$G:$G,WEAP!$A:$A,"")) ) | E6: =IFERROR( _xlfn.XLOOKUP($H6,WEAP!$F:$F,WEAP!$B:$B), IF($I6="","",_xlfn.XLOOKUP($I6,WEAP!$G:$G,WEAP!$B:$B,"")) ) | F6: =IFERROR( _xlfn.XLOOKUP($H6,WEAP!$F:$F,WEAP!$C:$C), IF($I6="","",_xlfn.XLOOKUP($I6,WEAP!$G:$G,WEAP!$C:$C,"")) ) | G6: =IFERROR( _xlfn.XLOOKUP($H6,WEAP!$F:$F,WEAP!$E:$E), IF($I6="","",_xlfn.XLOOKUP($I6,WEAP!$G:$G,WEAP!$E:$E,"")) ) | H6: =IFERROR( _xlfn.LET( _xlpm.txt,TRIM(B6), _xlpm.before,TRIM(_xlfn.TEXTBEFORE(_xlpm.txt,"\",-1)), _xlpm.after,_xlfn.TEXTAFTER(_xlpm.txt,"\"), _xlpm.lastToken,TRIM(_xlfn.TEXTAFTER(_xlpm.before," ",-1)), _xlpm.isReach,LOWER(TRIM(_xlpm.after))="reach", _xlpm.cleaned, IF( ISNUMBER(--_xlpm.lastToken), _xlfn.TEXTBEFORE(_xlpm.before," ",-1) & " \ " & _xlpm.after, _xlpm.txt ), IF(_xlpm.isReach,_xlpm.txt,TRIM(_xlpm.cleaned)) ), B6 ) -> Bear River at Camp Far West | I6: =IFERROR( _xlfn.LET( _xlpm.txt,B6, _xlpm.before,TRIM(_xlfn.TEXTBEFORE(_xlpm.txt,"\")), _xlpm.after,TRIM(_xlfn.TEXTAFTER(_xlpm.txt,"\")), _xlpm.lastToken,TRIM(_xlfn.TEXTAFTER(_xlpm.before," ",-1)), _xlpm.isNum,IFERROR(ISNUMBER(--_xlpm.lastToken),FALSE), IF( OR( LOWER(_xlpm.after)="headflow", LOWER(_xlpm.after)="reach" ), "", IF( _xlpm.isNum, _xlpm.lastToken & " \ " & _xlpm.after, "" ) ) ), "" )
A7: American River at Folsom | B7: American River at Folsom | C7: SacWAM | D7: =IFERROR( _xlfn.XLOOKUP($H7,WEAP!$F:$F,WEAP!$A:$A), IF($I7="","",_xlfn.XLOOKUP($I7,WEAP!$G:$G,WEAP!$A:$A,"")) ) | E7: =IFERROR( _xlfn.XLOOKUP($H7,WEAP!$F:$F,WEAP!$B:$B), IF($I7="","",_xlfn.XLOOKUP($I7,WEAP!$G:$G,WEAP!$B:$B,"")) ) | F7: =IFERROR( _xlfn.XLOOKUP($H7,WEAP!$F:$F,WEAP!$C:$C), IF($I7="","",_xlfn.XLOOKUP($I7,WEAP!$G:$G,WEAP!$C:$C,"")) ) | G7: =IFERROR( _xlfn.XLOOKUP($H7,WEAP!$F:$F,WEAP!$E:$E), IF($I7="","",_xlfn.XLOOKUP($I7,WEAP!$G:$G,WEAP!$E:$E,"")) ) | H7: =IFERROR( _xlfn.LET( _xlpm.txt,TRIM(B7), _xlpm.before,TRIM(_xlfn.TEXTBEFORE(_xlpm.txt,"\",-1)), _xlpm.after,_xlfn.TEXTAFTER(_xlpm.txt,"\"), _xlpm.lastToken,TRIM(_xlfn.TEXTAFTER(_xlpm.before," ",-1)), _xlpm.isReach,LOWER(TRIM(_xlpm.after))="reach", _xlpm.cleaned, IF( ISNUMBER(--_xlpm.lastToken), _xlfn.TEXTBEFORE(_xlpm.before," ",-1) & " \ " & _xlpm.after, _xlpm.txt ), IF(_xlpm.isReach,_xlpm.txt,TRIM(_xlpm.cleaned)) ), B7 ) -> American River at Folsom | I7: =IFERROR( _xlfn.LET( _xlpm.txt,B7, _xlpm.before,TRIM(_xlfn.TEXTBEFORE(_xlpm.txt,"\")), _xlpm.after,TRIM(_xlfn.TEXTAFTER(_xlpm.txt,"\")), _xlpm.lastToken,TRIM(_xlfn.TEXTAFTER(_xlpm.before," ",-1)), _xlpm.isNum,IFERROR(ISNUMBER(--_xlpm.lastToken),FALSE), IF( OR( LOWER(_xlpm.after)="headflow", LOWER(_xlpm.after)="reach" ), "", IF( _xlpm.isNum, _xlpm.lastToken & " \ " & _xlpm.after, "" ) ) ), "" )
A8: Stony Creek at Black Butte | B8: Stony Creek at Black Butte | C8: SacWAM | D8: =IFERROR( _xlfn.XLOOKUP($H8,WEAP!$F:$F,WEAP!$A:$A), IF($I8="","",_xlfn.XLOOKUP($I8,WEAP!$G:$G,WEAP!$A:$A,"")) ) | E8: =IFERROR( _xlfn.XLOOKUP($H8,WEAP!$F:$F,WEAP!$B:$B), IF($I8="","",_xlfn.XLOOKUP($I8,WEAP!$G:$G,WEAP!$B:$B,"")) ) | F8: =IFERROR( _xlfn.XLOOKUP($H8,WEAP!$F:$F,WEAP!$C:$C), IF($I8="","",_xlfn.XLOOKUP($I8,WEAP!$G:$G,WEAP!$C:$C,"")) ) | G8: =IFERROR( _xlfn.XLOOKUP($H8,WEAP!$F:$F,WEAP!$E:$E), IF($I8="","",_xlfn.XLOOKUP($I8,WEAP!$G:$G,WEAP!$E:$E,"")) ) | H8: =IFERROR( _xlfn.LET( _xlpm.txt,TRIM(B8), _xlpm.before,TRIM(_xlfn.TEXTBEFORE(_xlpm.txt,"\",-1)), _xlpm.after,_xlfn.TEXTAFTER(_xlpm.txt,"\"), _xlpm.lastToken,TRIM(_xlfn.TEXTAFTER(_xlpm.before," ",-1)), _xlpm.isReach,LOWER(TRIM(_xlpm.after))="reach", _xlpm.cleaned, IF( ISNUMBER(--_xlpm.lastToken), _xlfn.TEXTBEFORE(_xlpm.before," ",-1) & " \ " & _xlpm.after, _xlpm.txt ), IF(_xlpm.isReach,_xlpm.txt,TRIM(_xlpm.cleaned)) ), B8 ) -> Stony Creek at Black Butte | I8: =IFERROR( _xlfn.LET( _xlpm.txt,B8, _xlpm.before,TRIM(_xlfn.TEXTBEFORE(_xlpm.txt,"\")), _xlpm.after,TRIM(_xlfn.TEXTAFTER(_xlpm.txt,"\")), _xlpm.lastToken,TRIM(_xlfn.TEXTAFTER(_xlpm.before," ",-1)), _xlpm.isNum,IFERROR(ISNUMBER(--_xlpm.lastToken),FALSE), IF( OR( LOWER(_xlpm.after)="headflow", LOWER(_xlpm.after)="reach" ), "", IF( _xlpm.isNum, _xlpm.lastToken & " \ " & _xlpm.after, "" ) ) ), "" )
A9: Cache Creek at Rumsey | B9: Cache Creek at Rumsey | C9: SacWAM | D9: =IFERROR( _xlfn.XLOOKUP($H9,WEAP!$F:$F,WEAP!$A:$A), IF($I9="","",_xlfn.XLOOKUP($I9,WEAP!$G:$G,WEAP!$A:$A,"")) ) | E9: =IFERROR( _xlfn.XLOOKUP($H9,WEAP!$F:$F,WEAP!$B:$B), IF($I9="","",_xlfn.XLOOKUP($I9,WEAP!$G:$G,WEAP!$B:$B,"")) ) | F9: =IFERROR( _xlfn.XLOOKUP($H9,WEAP!$F:$F,WEAP!$C:$C), IF($I9="","",_xlfn.XLOOKUP($I9,WEAP!$G:$G,WEAP!$C:$C,"")) ) | G9: =IFERROR( _xlfn.XLOOKUP($H9,WEAP!$F:$F,WEAP!$E:$E), IF($I9="","",_xlfn.XLOOKUP($I9,WEAP!$G:$G,WEAP!$E:$E,"")) ) | H9: =IFERROR( _xlfn.LET( _xlpm.txt,TRIM(B9), _xlpm.before,TRIM(_xlfn.TEXTBEFORE(_xlpm.txt,"\",-1)), _xlpm.after,_xlfn.TEXTAFTER(_xlpm.txt,"\"), _xlpm.lastToken,TRIM(_xlfn.TEXTAFTER(_xlpm.before," ",-1)), _xlpm.isReach,LOWER(TRIM(_xlpm.after))="reach", _xlpm.cleaned, IF( ISNUMBER(--_xlpm.lastToken), _xlfn.TEXTBEFORE(_xlpm.before," ",-1) & " \ " & _xlpm.after, _xlpm.txt ), IF(_xlpm.isReach,_xlpm.txt,TRIM(_xlpm.cleaned)) ), B9 ) -> Cache Creek at Rumsey | I9: =IFERROR( _xlfn.LET( _xlpm.txt,B9, _xlpm.before,TRIM(_xlfn.TEXTBEFORE(_xlpm.txt,"\")), _xlpm.after,TRIM(_xlfn.TEXTAFTER(_xlpm.txt,"\")), _xlpm.lastToken,TRIM(_xlfn.TEXTAFTER(_xlpm.before," ",-1)), _xlpm.isNum,IFERROR(ISNUMBER(--_xlpm.lastToken),FALSE), IF( OR( LOWER(_xlpm.after)="headflow", LOWER(_xlpm.after)="reach" ), "", IF( _xlpm.isNum, _xlpm.lastToken & " \ " & _xlpm.after, "" ) ) ), "" )
A10: Putah Creek at Monticello | B10: Putah Creek at Monticello | C10: SacWAM | D10: =IFERROR( _xlfn.XLOOKUP($H10,WEAP!$F:$F,WEAP!$A:$A), IF($I10="","",_xlfn.XLOOKUP($I10,WEAP!$G:$G,WEAP!$A:$A,"")) ) | E10: =IFERROR( _xlfn.XLOOKUP($H10,WEAP!$F:$F,WEAP!$B:$B), IF($I10="","",_xlfn.XLOOKUP($I10,WEAP!$G:$G,WEAP!$B:$B,"")) ) | F10: =IFERROR( _xlfn.XLOOKUP($H10,WEAP!$F:$F,WEAP!$C:$C), IF($I10="","",_xlfn.XLOOKUP($I10,WEAP!$G:$G,WEAP!$C:$C,"")) ) | G10: =IFERROR( _xlfn.XLOOKUP($H10,WEAP!$F:$F,WEAP!$E:$E), IF($I10="","",_xlfn.XLOOKUP($I10,WEAP!$G:$G,WEAP!$E:$E,"")) ) | H10: =IFERROR( _xlfn.LET( _xlpm.txt,TRIM(B10), _xlpm.before,TRIM(_xlfn.TEXTBEFORE(_xlpm.txt,"\",-1)), _xlpm.after,_xlfn.TEXTAFTER(_xlpm.txt,"\"), _xlpm.lastToken,TRIM(_xlfn.TEXTAFTER(_xlpm.before," ",-1)), _xlpm.isReach,LOWER(TRIM(_xlpm.after))="reach", _xlpm.cleaned, IF( ISNUMBER(--_xlpm.lastToken), _xlfn.TEXTBEFORE(_xlpm.before," ",-1) & " \ " & _xlpm.after, _xlpm.txt ), IF(_xlpm.isReach,_xlpm.txt,TRIM(_xlpm.cleaned)) ), B10 ) -> Putah Creek at Monticello | I10: =IFERROR( _xlfn.LET( _xlpm.txt,B10, _xlpm.before,TRIM(_xlfn.TEXTBEFORE(_xlpm.txt,"\")), _xlpm.after,TRIM(_xlfn.TEXTAFTER(_xlpm.txt,"\")), _xlpm.lastToken,TRIM(_xlfn.TEXTAFTER(_xlpm.before," ",-1)), _xlpm.isNum,IFERROR(ISNUMBER(--_xlpm.lastToken),FALSE), IF( OR( LOWER(_xlpm.after)="headflow", LOWER(_xlpm.after)="reach" ), "", IF( _xlpm.isNum, _xlpm.lastToken & " \ " & _xlpm.after, "" ) ) ), "" )
A11: Cosumnes River at Michigan Bar | B11: Cosumnes River at Michigan Bar | C11: SacWAM | D11: =IFERROR( _xlfn.XLOOKUP($H11,WEAP!$F:$F,WEAP!$A:$A), IF($I11="","",_xlfn.XLOOKUP($I11,WEAP!$G:$G,WEAP!$A:$A,"")) ) | E11: =IFERROR( _xlfn.XLOOKUP($H11,WEAP!$F:$F,WEAP!$B:$B), IF($I11="","",_xlfn.XLOOKUP($I11,WEAP!$G:$G,WEAP!$B:$B,"")) ) | F11: =IFERROR( _xlfn.XLOOKUP($H11,WEAP!$F:$F,WEAP!$C:$C), IF($I11="","",_xlfn.XLOOKUP($I11,WEAP!$G:$G,WEAP!$C:$C,"")) ) | G11: =IFERROR( _xlfn.XLOOKUP($H11,WEAP!$F:$F,WEAP!$E:$E), IF($I11="","",_xlfn.XLOOKUP($I11,WEAP!$G:$G,WEAP!$E:$E,"")) ) | H11: =IFERROR( _xlfn.LET( _xlpm.txt,TRIM(B11), _xlpm.before,TRIM(_xlfn.TEXTBEFORE(_xlpm.txt,"\",-1)), _xlpm.after,_xlfn.TEXTAFTER(_xlpm.txt,"\"), _xlpm.lastToken,TRIM(_xlfn.TEXTAFTER(_xlpm.before," ",-1)), _xlpm.isReach,LOWER(TRIM(_xlpm.after))="reach", _xlpm.cleaned, IF( ISNUMBER(--_xlpm.lastToken), _xlfn.TEXTBEFORE(_xlpm.before," ",-1) & " \ " & _xlpm.after, _xlpm.txt ), IF(_xlpm.isReach,_xlpm.txt,TRIM(_xlpm.cleaned)) ), B11 ) -> Cosumnes River at Michigan Bar | I11: =IFERROR( _xlfn.LET( _xlpm.txt,B11, _xlpm.before,TRIM(_xlfn.TEXTBEFORE(_xlpm.txt,"\")), _xlpm.after,TRIM(_xlfn.TEXTAFTER(_xlpm.txt,"\")), _xlpm.lastToken,TRIM(_xlfn.TEXTAFTER(_xlpm.before," ",-1)), _xlpm.isNum,IFERROR(ISNUMBER(--_xlpm.lastToken),FALSE), IF( OR( LOWER(_xlpm.after)="headflow", LOWER(_xlpm.after)="reach" ), "", IF( _xlpm.isNum, _xlpm.lastToken & " \ " & _xlpm.after, "" ) ) ), "" )
A12: Mokelumne River at Mokelumne Hill | B12: Mokelumne River at Mokelumne Hill | C12: SacWAM | D12: =IFERROR( _xlfn.XLOOKUP($H12,WEAP!$F:$F,WEAP!$A:$A), IF($I12="","",_xlfn.XLOOKUP($I12,WEAP!$G:$G,WEAP!$A:$A,"")) ) | E12: =IFERROR( _xlfn.XLOOKUP($H12,WEAP!$F:$F,WEAP!$B:$B), IF($I12="","",_xlfn.XLOOKUP($I12,WEAP!$G:$G,WEAP!$B:$B,"")) ) | F12: =IFERROR( _xlfn.XLOOKUP($H12,WEAP!$F:$F,WEAP!$C:$C), IF($I12="","",_xlfn.XLOOKUP($I12,WEAP!$G:$G,WEAP!$C:$C,"")) ) | G12: =IFERROR( _xlfn.XLOOKUP($H12,WEAP!$F:$F,WEAP!$E:$E), IF($I12="","",_xlfn.XLOOKUP($I12,WEAP!$G:$G,WEAP!$E:$E,"")) ) | H12: =IFERROR( _xlfn.LET( _xlpm.txt,TRIM(B12), _xlpm.before,TRIM(_xlfn.TEXTBEFORE(_xlpm.txt,"\",-1)), _xlpm.after,_xlfn.TEXTAFTER(_xlpm.txt,"\"), _xlpm.lastToken,TRIM(_xlfn.TEXTAFTER(_xlpm.before," ",-1)), _xlpm.isReach,LOWER(TRIM(_xlpm.after))="reach", _xlpm.cleaned, IF( ISNUMBER(--_xlpm.lastToken), _xlfn.TEXTBEFORE(_xlpm.before," ",-1) & " \ " & _xlpm.after, _xlpm.txt ), IF(_xlpm.isReach,_xlpm.txt,TRIM(_xlpm.cleaned)) ), B12 ) -> Mokelumne River at Mokelumne Hill | I12: =IFERROR( _xlfn.LET( _xlpm.txt,B12, _xlpm.before,TRIM(_xlfn.TEXTBEFORE(_xlpm.txt,"\")), _xlpm.after,TRIM(_xlfn.TEXTAFTER(_xlpm.txt,"\")), _xlpm.lastToken,TRIM(_xlfn.TEXTAFTER(_xlpm.before," ",-1)), _xlpm.isNum,IFERROR(ISNUMBER(--_xlpm.lastToken),FALSE), IF( OR( LOWER(_xlpm.after)="headflow", LOWER(_xlpm.after)="reach" ), "", IF( _xlpm.isNum, _xlpm.lastToken & " \ " & _xlpm.after, "" ) ) ), "" )
A13: Mokelumne River at Camanche | B13: Mokelumne River at Camanche | C13: SacWAM | D13: =IFERROR( _xlfn.XLOOKUP($H13,WEAP!$F:$F,WEAP!$A:$A), IF($I13="","",_xlfn.XLOOKUP($I13,WEAP!$G:$G,WEAP!$A:$A,"")) ) | E13: =IFERROR( _xlfn.XLOOKUP($H13,WEAP!$F:$F,WEAP!$B:$B), IF($I13="","",_xlfn.XLOOKUP($I13,WEAP!$G:$G,WEAP!$B:$B,"")) ) | F13: =IFERROR( _xlfn.XLOOKUP($H13,WEAP!$F:$F,WEAP!$C:$C), IF($I13="","",_xlfn.XLOOKUP($I13,WEAP!$G:$G,WEAP!$C:$C,"")) ) | G13: =IFERROR( _xlfn.XLOOKUP($H13,WEAP!$F:$F,WEAP!$E:$E), IF($I13="","",_xlfn.XLOOKUP($I13,WEAP!$G:$G,WEAP!$E:$E,"")) ) | H13: =IFERROR( _xlfn.LET( _xlpm.txt,TRIM(B13), _xlpm.before,TRIM(_xlfn.TEXTBEFORE(_xlpm.txt,"\",-1)), _xlpm.after,_xlfn.TEXTAFTER(_xlpm.txt,"\"), _xlpm.lastToken,TRIM(_xlfn.TEXTAFTER(_xlpm.before," ",-1)), _xlpm.isReach,LOWER(TRIM(_xlpm.after))="reach", _xlpm.cleaned, IF( ISNUMBER(--_xlpm.lastToken), _xlfn.TEXTBEFORE(_xlpm.before," ",-1) & " \ " & _xlpm.after, _xlpm.txt ), IF(_xlpm.isReach,_xlpm.txt,TRIM(_xlpm.cleaned)) ), B13 ) -> Mokelumne River at Camanche | I13: =IFERROR( _xlfn.LET( _xlpm.txt,B13, _xlpm.before,TRIM(_xlfn.TEXTBEFORE(_xlpm.txt,"\")), _xlpm.after,TRIM(_xlfn.TEXTAFTER(_xlpm.txt,"\")), _xlpm.lastToken,TRIM(_xlfn.TEXTAFTER(_xlpm.before," ",-1)), _xlpm.isNum,IFERROR(ISNUMBER(--_xlpm.lastToken),FALSE), IF( OR( LOWER(_xlpm.after)="headflow", LOWER(_xlpm.after)="reach" ), "", IF( _xlpm.isNum, _xlpm.lastToken & " \ " & _xlpm.after, "" ) ) ), "" )
... A16: Misc Sac Valley Creeks | B16: Misc Sac Valley Creeks | C16: SacWAM | D16: =IFERROR( _xlfn.XLOOKUP($H16,WEAP!$F:$F,WEAP!$A:$A), IF($I16="","",_xlfn.XLOOKUP($I16,WEAP!$G:$G,WEAP!$A:$A,"")) ) | E16: =IFERROR( _xlfn.XLOOKUP($H16,WEAP!$F:$F,WEAP!$B:$B), IF($I16="","",_xlfn.XLOOKUP($I16,WEAP!$G:$G,WEAP!$B:$B,"")) ) | F16: =IFERROR( _xlfn.XLOOKUP($H16,WEAP!$F:$F,WEAP!$C:$C), IF($I16="","",_xlfn.XLOOKUP($I16,WEAP!$G:$G,WEAP!$C:$C,"")) ) | G16: =IFERROR( _xlfn.XLOOKUP($H16,WEAP!$F:$F,WEAP!$E:$E), IF($I16="","",_xlfn.XLOOKUP($I16,WEAP!$G:$G,WEAP!$E:$E,"")) ) | H16: =IFERROR( _xlfn.LET( _xlpm.txt,TRIM(B16), _xlpm.before,TRIM(_xlfn.TEXTBEFORE(_xlpm.txt,"\",-1)), _xlpm.after,_xlfn.TEXTAFTER(_xlpm.txt,"\"), _xlpm.lastToken,TRIM(_xlfn.TEXTAFTER(_xlpm.before," ",-1)), _xlpm.isReach,LOWER(TRIM(_xlpm.after))="reach", _xlpm.cleaned, IF( ISNUMBER(--_xlpm.lastToken), _xlfn.TEXTBEFORE(_xlpm.before," ",-1) & " \ " & _xlpm.after, _xlpm.txt ), IF(_xlpm.isReach,_xlpm.txt,TRIM(_xlpm.cleaned)) ), B16 ) -> Misc Sac Valley Creeks | I16: =IFERROR( _xlfn.LET( _xlpm.txt,B16, _xlpm.before,TRIM(_xlfn.TEXTBEFORE(_xlpm.txt,"\")), _xlpm.after,TRIM(_xlfn.TEXTAFTER(_xlpm.txt,"\")), _xlpm.lastToken,TRIM(_xlfn.TEXTAFTER(_xlpm.before," ",-1)), _xlpm.isNum,IFERROR(ISNUMBER(--_xlpm.lastToken),FALSE), IF( OR( LOWER(_xlpm.after)="headflow", LOWER(_xlpm.after)="reach" ), "", IF( _xlpm.isNum, _xlpm.lastToken & " \ " & _xlpm.after, "" ) ) ), "" )
B17: SWP Allocations\Final_Allocation\SWP_percent_delivery | C17: SacWAM | D17: =IFERROR( _xlfn.XLOOKUP($H17,WEAP!$F:$F,WEAP!$A:$A), IF($I17="","",_xlfn.XLOOKUP($I17,WEAP!$G:$G,WEAP!$A:$A,"")) ) | E17: =IFERROR( _xlfn.XLOOKUP($H17,WEAP!$F:$F,WEAP!$B:$B), IF($I17="","",_xlfn.XLOOKUP($I17,WEAP!$G:$G,WEAP!$B:$B,"")) ) | F17: =IFERROR( _xlfn.XLOOKUP($H17,WEAP!$F:$F,WEAP!$C:$C), IF($I17="","",_xlfn.XLOOKUP($I17,WEAP!$G:$G,WEAP!$C:$C,"")) ) | G17: =IFERROR( _xlfn.XLOOKUP($H17,WEAP!$F:$F,WEAP!$E:$E), IF($I17="","",_xlfn.XLOOKUP($I17,WEAP!$G:$G,WEAP!$E:$E,"")) ) | H17: =IFERROR( _xlfn.LET( _xlpm.txt,TRIM(B17), _xlpm.before,TRIM(_xlfn.TEXTBEFORE(_xlpm.txt,"\",-1)), _xlpm.after,_xlfn.TEXTAFTER(_xlpm.txt,"\"), _xlpm.lastToken,TRIM(_xlfn.TEXTAFTER(_xlpm.before," ",-1)), _xlpm.isReach,LOWER(TRIM(_xlpm.after))="reach", _xlpm.cleaned, IF( ISNUMBER(--_xlpm.lastToken), _xlfn.TEXTBEFORE(_xlpm.before," ",-1) & " \ " & _xlpm.after, _xlpm.txt ), IF(_xlpm.isReach,_xlpm.txt,TRIM(_xlpm.cleaned)) ), B17 ) -> SWP Allocations\Final_Allocation\SWP_percent_delivery | I17: =IFERROR( _xlfn.LET( _xlpm.txt,B17, _xlpm.before,TRIM(_xlfn.TEXTBEFORE(_xlpm.txt,"\")), _xlpm.after,TRIM(_xlfn.TEXTAFTER(_xlpm.txt,"\")), _xlpm.lastToken,TRIM(_xlfn.TEXTAFTER(_xlpm.before," ",-1)), _xlpm.isNum,IFERROR(ISNUMBER(--_xlpm.lastToken),FALSE), IF( OR( LOWER(_xlpm.after)="headflow", LOWER(_xlpm.after)="reach" ), "", IF( _xlpm.isNum, _xlpm.lastToken & " \ " & _xlpm.after, "" ) ) ), "" )
B18: CVP Allocations\System\Percent_Alloc_AG | C18: SacWAM | D18: =IFERROR( _xlfn.XLOOKUP($H18,WEAP!$F:$F,WEAP!$A:$A), IF($I18="","",_xlfn.XLOOKUP($I18,WEAP!$G:$G,WEAP!$A:$A,"")) ) | E18: =IFERROR( _xlfn.XLOOKUP($H18,WEAP!$F:$F,WEAP!$B:$B), IF($I18="","",_xlfn.XLOOKUP($I18,WEAP!$G:$G,WEAP!$B:$B,"")) ) | F18: =IFERROR( _xlfn.XLOOKUP($H18,WEAP!$F:$F,WEAP!$C:$C), IF($I18="","",_xlfn.XLOOKUP($I18,WEAP!$G:$G,WEAP!$C:$C,"")) ) | G18: =IFERROR( _xlfn.XLOOKUP($H18,WEAP!$F:$F,WEAP!$E:$E), IF($I18="","",_xlfn.XLOOKUP($I18,WEAP!$G:$G,WEAP!$E:$E,"")) ) | H18: =IFERROR( _xlfn.LET( _xlpm.txt,TRIM(B18), _xlpm.before,TRIM(_xlfn.TEXTBEFORE(_xlpm.txt,"\",-1)), _xlpm.after,_xlfn.TEXTAFTER(_xlpm.txt,"\"), _xlpm.lastToken,TRIM(_xlfn.TEXTAFTER(_xlpm.before," ",-1)), _xlpm.isReach,LOWER(TRIM(_xlpm.after))="reach", _xlpm.cleaned, IF( ISNUMBER(--_xlpm.lastToken), _xlfn.TEXTBEFORE(_xlpm.before," ",-1) & " \ " & _xlpm.after, _xlpm.txt ), IF(_xlpm.isReach,_xlpm.txt,TRIM(_xlpm.cleaned)) ), B18 ) -> CVP Allocations\System\Percent_Alloc_AG | I18: =IFERROR( _xlfn.LET( _xlpm.txt,B18, _xlpm.before,TRIM(_xlfn.TEXTBEFORE(_xlpm.txt,"\")), _xlpm.after,TRIM(_xlfn.TEXTAFTER(_xlpm.txt,"\")), _xlpm.lastToken,TRIM(_xlfn.TEXTAFTER(_xlpm.before," ",-1)), _xlpm.isNum,IFERROR(ISNUMBER(--_xlpm.lastToken),FALSE), IF( OR( LOWER(_xlpm.after)="headflow", LOWER(_xlpm.after)="reach" ), "", IF( _xlpm.isNum, _xlpm.lastToken & " \ " & _xlpm.after, "" ) ) ), "" )
B19: CVP Allocations\South\Percent_Alloc_AG | C19: SacWAM | D19: =IFERROR( _xlfn.XLOOKUP($H19,WEAP!$F:$F,WEAP!$A:$A), IF($I19="","",_xlfn.XLOOKUP($I19,WEAP!$G:$G,WEAP!$A:$A,"")) ) | E19: =IFERROR( _xlfn.XLOOKUP($H19,WEAP!$F:$F,WEAP!$B:$B), IF($I19="","",_xlfn.XLOOKUP($I19,WEAP!$G:$G,WEAP!$B:$B,"")) ) | F19: =IFERROR( _xlfn.XLOOKUP($H19,WEAP!$F:$F,WEAP!$C:$C), IF($I19="","",_xlfn.XLOOKUP($I19,WEAP!$G:$G,WEAP!$C:$C,"")) ) | G19: =IFERROR( _xlfn.XLOOKUP($H19,WEAP!$F:$F,WEAP!$E:$E), IF($I19="","",_xlfn.XLOOKUP($I19,WEAP!$G:$G,WEAP!$E:$E,"")) ) | H19: =IFERROR( _xlfn.LET( _xlpm.txt,TRIM(B19), _xlpm.before,TRIM(_xlfn.TEXTBEFORE(_xlpm.txt,"\",-1)), _xlpm.after,_xlfn.TEXTAFTER(_xlpm.txt,"\"), _xlpm.lastToken,TRIM(_xlfn.TEXTAFTER(_xlpm.before," ",-1)), _xlpm.isReach,LOWER(TRIM(_xlpm.after))="reach", _xlpm.cleaned, IF( ISNUMBER(--_xlpm.lastToken), _xlfn.TEXTBEFORE(_xlpm.before," ",-1) & " \ " & _xlpm.after, _xlpm.txt ), IF(_xlpm.isReach,_xlpm.txt,TRIM(_xlpm.cleaned)) ), B19 ) -> CVP Allocations\South\Percent_Alloc_AG | I19: =IFERROR( _xlfn.LET( _xlpm.txt,B19, _xlpm.before,TRIM(_xlfn.TEXTBEFORE(_xlpm.txt,"\")), _xlpm.after,TRIM(_xlfn.TEXTAFTER(_xlpm.txt,"\")), _xlpm.lastToken,TRIM(_xlfn.TEXTAFTER(_xlpm.before," ",-1)), _xlpm.isNum,IFERROR(ISNUMBER(--_xlpm.lastToken),FALSE), IF( OR( LOWER(_xlpm.after)="headflow", LOWER(_xlpm.after)="reach" ), "", IF( _xlpm.isNum, _xlpm.lastToken & " \ " & _xlpm.after, "" ) ) ), "" )
B20: CVP Allocations\System\Percent_Alloc_MI | C20: SacWAM | D20: =IFERROR( _xlfn.XLOOKUP($H20,WEAP!$F:$F,WEAP!$A:$A), IF($I20="","",_xlfn.XLOOKUP($I20,WEAP!$G:$G,WEAP!$A:$A,"")) ) | E20: =IFERROR( _xlfn.XLOOKUP($H20,WEAP!$F:$F,WEAP!$B:$B), IF($I20="","",_xlfn.XLOOKUP($I20,WEAP!$G:$G,WEAP!$B:$B,"")) ) | F20: =IFERROR( _xlfn.XLOOKUP($H20,WEAP!$F:$F,WEAP!$C:$C), IF($I20="","",_xlfn.XLOOKUP($I20,WEAP!$G:$G,WEAP!$C:$C,"")) ) | G20: =IFERROR( _xlfn.XLOOKUP($H20,WEAP!$F:$F,WEAP!$E:$E), IF($I20="","",_xlfn.XLOOKUP($I20,WEAP!$G:$G,WEAP!$E:$E,"")) ) | H20: =IFERROR( _xlfn.LET( _xlpm.txt,TRIM(B20), _xlpm.before,TRIM(_xlfn.TEXTBEFORE(_xlpm.txt,"\",-1)), _xlpm.after,_xlfn.TEXTAFTER(_xlpm.txt,"\"), _xlpm.lastToken,TRIM(_xlfn.TEXTAFTER(_xlpm.before," ",-1)), _xlpm.isReach,LOWER(TRIM(_xlpm.after))="reach", _xlpm.cleaned, IF( ISNUMBER(--_xlpm.lastToken), _xlfn.TEXTBEFORE(_xlpm.before," ",-1) & " \ " & _xlpm.after, _xlpm.txt ), IF(_xlpm.isReach,_xlpm.txt,TRIM(_xlpm.cleaned)) ), B20 ) -> CVP Allocations\System\Percent_Alloc_MI | I20: =IFERROR( _xlfn.LET( _xlpm.txt,B20, _xlpm.before,TRIM(_xlfn.TEXTBEFORE(_xlpm.txt,"\")), _xlpm.after,TRIM(_xlfn.TEXTAFTER(_xlpm.txt,"\")), _xlpm.lastToken,TRIM(_xlfn.TEXTAFTER(_xlpm.before," ",-1)), _xlpm.isNum,IFERROR(ISNUMBER(--_xlpm.lastToken),FALSE), IF( OR( LOWER(_xlpm.after)="headflow", LOWER(_xlpm.after)="reach" ), "", IF( _xlpm.isNum, _xlpm.lastToken & " \ " & _xlpm.after, "" ) ) ), "" )
B21: CVP Allocations\South\Percent_Alloc_MI | C21: SacWAM | D21: =IFERROR( _xlfn.XLOOKUP($H21,WEAP!$F:$F,WEAP!$A:$A), IF($I21="","",_xlfn.XLOOKUP($I21,WEAP!$G:$G,WEAP!$A:$A,"")) ) | E21: =IFERROR( _xlfn.XLOOKUP($H21,WEAP!$F:$F,WEAP!$B:$B), IF($I21="","",_xlfn.XLOOKUP($I21,WEAP!$G:$G,WEAP!$B:$B,"")) ) | F21: =IFERROR( _xlfn.XLOOKUP($H21,WEAP!$F:$F,WEAP!$C:$C), IF($I21="","",_xlfn.XLOOKUP($I21,WEAP!$G:$G,WEAP!$C:$C,"")) ) | G21: =IFERROR( _xlfn.XLOOKUP($H21,WEAP!$F:$F,WEAP!$E:$E), IF($I21="","",_xlfn.XLOOKUP($I21,WEAP!$G:$G,WEAP!$E:$E,"")) ) | H21: =IFERROR( _xlfn.LET( _xlpm.txt,TRIM(B21), _xlpm.before,TRIM(_xlfn.TEXTBEFORE(_xlpm.txt,"\",-1)), _xlpm.after,_xlfn.TEXTAFTER(_xlpm.txt,"\"), _xlpm.lastToken,TRIM(_xlfn.TEXTAFTER(_xlpm.before," ",-1)), _xlpm.isReach,LOWER(TRIM(_xlpm.after))="reach", _xlpm.cleaned, IF( ISNUMBER(--_xlpm.lastToken), _xlfn.TEXTBEFORE(_xlpm.before," ",-1) & " \ " & _xlpm.after, _xlpm.txt ), IF(_xlpm.isReach,_xlpm.txt,TRIM(_xlpm.cleaned)) ), B21 ) -> CVP Allocations\South\Percent_Alloc_MI | I21: =IFERROR( _xlfn.LET( _xlpm.txt,B21, _xlpm.before,TRIM(_xlfn.TEXTBEFORE(_xlpm.txt,"\")), _xlpm.after,TRIM(_xlfn.TEXTAFTER(_xlpm.txt,"\")), _xlpm.lastToken,TRIM(_xlfn.TEXTAFTER(_xlpm.before," ",-1)), _xlpm.isNum,IFERROR(ISNUMBER(--_xlpm.lastToken),FALSE), IF( OR( LOWER(_xlpm.after)="headflow", LOWER(_xlpm.after)="reach" ), "", IF( _xlpm.isNum, _xlpm.lastToken & " \ " & _xlpm.after, "" ) ) ), "" )
B22: CVP Allocations\System\Percent_Alloc_SC | C22: SacWAM | D22: =IFERROR( _xlfn.XLOOKUP($H22,WEAP!$F:$F,WEAP!$A:$A), IF($I22="","",_xlfn.XLOOKUP($I22,WEAP!$G:$G,WEAP!$A:$A,"")) ) | E22: =IFERROR( _xlfn.XLOOKUP($H22,WEAP!$F:$F,WEAP!$B:$B), IF($I22="","",_xlfn.XLOOKUP($I22,WEAP!$G:$G,WEAP!$B:$B,"")) ) | F22: =IFERROR( _xlfn.XLOOKUP($H22,WEAP!$F:$F,WEAP!$C:$C), IF($I22="","",_xlfn.XLOOKUP($I22,WEAP!$G:$G,WEAP!$C:$C,"")) ) | G22: =IFERROR( _xlfn.XLOOKUP($H22,WEAP!$F:$F,WEAP!$E:$E), IF($I22="","",_xlfn.XLOOKUP($I22,WEAP!$G:$G,WEAP!$E:$E,"")) ) | H22: =IFERROR( _xlfn.LET( _xlpm.txt,TRIM(B22), _xlpm.before,TRIM(_xlfn.TEXTBEFORE(_xlpm.txt,"\",-1)), _xlpm.after,_xlfn.TEXTAFTER(_xlpm.txt,"\"), _xlpm.lastToken,TRIM(_xlfn.TEXTAFTER(_xlpm.before," ",-1)), _xlpm.isReach,LOWER(TRIM(_xlpm.after))="reach", _xlpm.cleaned, IF( ISNUMBER(--_xlpm.lastToken), _xlfn.TEXTBEFORE(_xlpm.before," ",-1) & " \ " & _xlpm.after, _xlpm.txt ), IF(_xlpm.isReach,_xlpm.txt,TRIM(_xlpm.cleaned)) ), B22 ) -> CVP Allocations\System\Percent_Alloc_SC | I22: =IFERROR( _xlfn.LET( _xlpm.txt,B22, _xlpm.before,TRIM(_xlfn.TEXTBEFORE(_xlpm.txt,"\")), _xlpm.after,TRIM(_xlfn.TEXTAFTER(_xlpm.txt,"\")), _xlpm.lastToken,TRIM(_xlfn.TEXTAFTER(_xlpm.before," ",-1)), _xlpm.isNum,IFERROR(ISNUMBER(--_xlpm.lastToken),FALSE), IF( OR( LOWER(_xlpm.after)="headflow", LOWER(_xlpm.after)="reach" ), "", IF( _xlpm.isNum, _xlpm.lastToken & " \ " & _xlpm.after, "" ) ) ), "" )
B23: CVP Allocations\South\Percent_Alloc_EX | C23: SacWAM | D23: =IFERROR( _xlfn.XLOOKUP($H23,WEAP!$F:$F,WEAP!$A:$A), IF($I23="","",_xlfn.XLOOKUP($I23,WEAP!$G:$G,WEAP!$A:$A,"")) ) | E23: =IFERROR( _xlfn.XLOOKUP($H23,WEAP!$F:$F,WEAP!$B:$B), IF($I23="","",_xlfn.XLOOKUP($I23,WEAP!$G:$G,WEAP!$B:$B,"")) ) | F23: =IFERROR( _xlfn.XLOOKUP($H23,WEAP!$F:$F,WEAP!$C:$C), IF($I23="","",_xlfn.XLOOKUP($I23,WEAP!$G:$G,WEAP!$C:$C,"")) ) | G23: =IFERROR( _xlfn.XLOOKUP($H23,WEAP!$F:$F,WEAP!$E:$E), IF($I23="","",_xlfn.XLOOKUP($I23,WEAP!$G:$G,WEAP!$E:$E,"")) ) | H23: =IFERROR( _xlfn.LET( _xlpm.txt,TRIM(B23), _xlpm.before,TRIM(_xlfn.TEXTBEFORE(_xlpm.txt,"\",-1)), _xlpm.after,_xlfn.TEXTAFTER(_xlpm.txt,"\"), _xlpm.lastToken,TRIM(_xlfn.TEXTAFTER(_xlpm.before," ",-1)), _xlpm.isReach,LOWER(TRIM(_xlpm.after))="reach", _xlpm.cleaned, IF( ISNUMBER(--_xlpm.lastToken), _xlfn.TEXTBEFORE(_xlpm.before," ",-1) & " \ " & _xlpm.after, _xlpm.txt ), IF(_xlpm.isReach,_xlpm.txt,TRIM(_xlpm.cleaned)) ), B23 ) -> CVP Allocations\South\Percent_Alloc_EX | I23: =IFERROR( _xlfn.LET( _xlpm.txt,B23, _xlpm.before,TRIM(_xlfn.TEXTBEFORE(_xlpm.txt,"\")), _xlpm.after,TRIM(_xlfn.TEXTAFTER(_xlpm.txt,"\")), _xlpm.lastToken,TRIM(_xlfn.TEXTAFTER(_xlpm.before," ",-1)), _xlpm.isNum,IFERROR(ISNUMBER(--_xlpm.lastToken),FALSE), IF( OR( LOWER(_xlpm.after)="headflow", LOWER(_xlpm.after)="reach" ), "", IF( _xlpm.isNum, _xlpm.lastToken & " \ " & _xlpm.after, "" ) ) ), "" )
B24: CVP Allocations\System\Percent_Alloc_RFN | C24: SacWAM | D24: =IFERROR( _xlfn.XLOOKUP($H24,WEAP!$F:$F,WEAP!$A:$A), IF($I24="","",_xlfn.XLOOKUP($I24,WEAP!$G:$G,WEAP!$A:$A,"")) ) | E24: =IFERROR( _xlfn.XLOOKUP($H24,WEAP!$F:$F,WEAP!$B:$B), IF($I24="","",_xlfn.XLOOKUP($I24,WEAP!$G:$G,WEAP!$B:$B,"")) ) | F24: =IFERROR( _xlfn.XLOOKUP($H24,WEAP!$F:$F,WEAP!$C:$C), IF($I24="","",_xlfn.XLOOKUP($I24,WEAP!$G:$G,WEAP!$C:$C,"")) ) | G24: =IFERROR( _xlfn.XLOOKUP($H24,WEAP!$F:$F,WEAP!$E:$E), IF($I24="","",_xlfn.XLOOKUP($I24,WEAP!$G:$G,WEAP!$E:$E,"")) ) | H24: =IFERROR( _xlfn.LET( _xlpm.txt,TRIM(B24), _xlpm.before,TRIM(_xlfn.TEXTBEFORE(_xlpm.txt,"\",-1)), _xlpm.after,_xlfn.TEXTAFTER(_xlpm.txt,"\"), _xlpm.lastToken,TRIM(_xlfn.TEXTAFTER(_xlpm.before," ",-1)), _xlpm.isReach,LOWER(TRIM(_xlpm.after))="reach", _xlpm.cleaned, IF( ISNUMBER(--_xlpm.lastToken), _xlfn.TEXTBEFORE(_xlpm.before," ",-1) & " \ " & _xlpm.after, _xlpm.txt ), IF(_xlpm.isReach,_xlpm.txt,TRIM(_xlpm.cleaned)) ), B24 ) -> CVP Allocations\System\Percent_Alloc_RFN | I24: =IFERROR( _xlfn.LET( _xlpm.txt,B24, _xlpm.before,TRIM(_xlfn.TEXTBEFORE(_xlpm.txt,"\")), _xlpm.after,TRIM(_xlfn.TEXTAFTER(_xlpm.txt,"\")), _xlpm.lastToken,TRIM(_xlfn.TEXTAFTER(_xlpm.before," ",-1)), _xlpm.isNum,IFERROR(ISNUMBER(--_xlpm.lastToken),FALSE), IF( OR( LOWER(_xlpm.after)="headflow", LOWER(_xlpm.after)="reach" ), "", IF( _xlpm.isNum, _xlpm.lastToken & " \ " & _xlpm.after, "" ) ) ), "" )
B25: CVP Allocations\South\Percent_Alloc_RFS | C25: SacWAM | D25: =IFERROR( _xlfn.XLOOKUP($H25,WEAP!$F:$F,WEAP!$A:$A), IF($I25="","",_xlfn.XLOOKUP($I25,WEAP!$G:$G,WEAP!$A:$A,"")) ) | E25: =IFERROR( _xlfn.XLOOKUP($H25,WEAP!$F:$F,WEAP!$B:$B), IF($I25="","",_xlfn.XLOOKUP($I25,WEAP!$G:$G,WEAP!$B:$B,"")) ) | F25: =IFERROR( _xlfn.XLOOKUP($H25,WEAP!$F:$F,WEAP!$C:$C), IF($I25="","",_xlfn.XLOOKUP($I25,WEAP!$G:$G,WEAP!$C:$C,"")) ) | G25: =IFERROR( _xlfn.XLOOKUP($H25,WEAP!$F:$F,WEAP!$E:$E), IF($I25="","",_xlfn.XLOOKUP($I25,WEAP!$G:$G,WEAP!$E:$E,"")) ) | H25: =IFERROR( _xlfn.LET( _xlpm.txt,TRIM(B25), _xlpm.before,TRIM(_xlfn.TEXTBEFORE(_xlpm.txt,"\",-1)), _xlpm.after,_xlfn.TEXTAFTER(_xlpm.txt,"\"), _xlpm.lastToken,TRIM(_xlfn.TEXTAFTER(_xlpm.before," ",-1)), _xlpm.isReach,LOWER(TRIM(_xlpm.after))="reach", _xlpm.cleaned, IF( ISNUMBER(--_xlpm.lastToken), _xlfn.TEXTBEFORE(_xlpm.before," ",-1) & " \ " & _xlpm.after, _xlpm.txt ), IF(_xlpm.isReach,_xlpm.txt,TRIM(_xlpm.cleaned)) ), B25 ) -> CVP Allocations\South\Percent_Alloc_RFS | I25: =IFERROR( _xlfn.LET( _xlpm.txt,B25, _xlpm.before,TRIM(_xlfn.TEXTBEFORE(_xlpm.txt,"\")), _xlpm.after,TRIM(_xlfn.TEXTAFTER(_xlpm.txt,"\")), _xlpm.lastToken,TRIM(_xlfn.TEXTAFTER(_xlpm.before," ",-1)), _xlpm.isNum,IFERROR(ISNUMBER(--_xlpm.lastToken),FALSE), IF( OR( LOWER(_xlpm.after)="headflow", LOWER(_xlpm.after)="reach" ), "", IF( _xlpm.isNum, _xlpm.lastToken & " \ " & _xlpm.after, "" ) ) ), "" )
B26: San Luis\SWP\RuleCurve (Thousand AF) | C26: SacWAM | D26: =IFERROR( _xlfn.XLOOKUP($H26,WEAP!$F:$F,WEAP!$A:$A), IF($I26="","",_xlfn.XLOOKUP($I26,WEAP!$G:$G,WEAP!$A:$A,"")) ) | E26: =IFERROR( _xlfn.XLOOKUP($H26,WEAP!$F:$F,WEAP!$B:$B), IF($I26="","",_xlfn.XLOOKUP($I26,WEAP!$G:$G,WEAP!$B:$B,"")) ) | F26: =IFERROR( _xlfn.XLOOKUP($H26,WEAP!$F:$F,WEAP!$C:$C), IF($I26="","",_xlfn.XLOOKUP($I26,WEAP!$G:$G,WEAP!$C:$C,"")) ) | G26: =IFERROR( _xlfn.XLOOKUP($H26,WEAP!$F:$F,WEAP!$E:$E), IF($I26="","",_xlfn.XLOOKUP($I26,WEAP!$G:$G,WEAP!$E:$E,"")) ) | H26: =IFERROR( _xlfn.LET( _xlpm.txt,TRIM(B26), _xlpm.before,TRIM(_xlfn.TEXTBEFORE(_xlpm.txt,"\",-1)), _xlpm.after,_xlfn.TEXTAFTER(_xlpm.txt,"\"), _xlpm.lastToken,TRIM(_xlfn.TEXTAFTER(_xlpm.before," ",-1)), _xlpm.isReach,LOWER(TRIM(_xlpm.after))="reach", _xlpm.cleaned, IF( ISNUMBER(--_xlpm.lastToken), _xlfn.TEXTBEFORE(_xlpm.before," ",-1) & " \ " & _xlpm.after, _xlpm.txt ), IF(_xlpm.isReach,_xlpm.txt,TRIM(_xlpm.cleaned)) ), B26 ) -> San Luis\SWP\RuleCurve (Thousand AF) | I26: =IFERROR( _xlfn.LET( _xlpm.txt,B26, _xlpm.before,TRIM(_xlfn.TEXTBEFORE(_xlpm.txt,"\")), _xlpm.after,TRIM(_xlfn.TEXTAFTER(_xlpm.txt,"\")), _xlpm.lastToken,TRIM(_xlfn.TEXTAFTER(_xlpm.before," ",-1)), _xlpm.isNum,IFERROR(ISNUMBER(--_xlpm.lastToken),FALSE), IF( OR( LOWER(_xlpm.after)="headflow", LOWER(_xlpm.after)="reach" ), "", IF( _xlpm.isNum, _xlpm.lastToken & " \ " & _xlpm.after, "" ) ) ), "" )
B27: San Luis\SWP\RuleCurveCalc (Thousand AF) | C27: SacWAM | D27: =IFERROR( _xlfn.XLOOKUP($H27,WEAP!$F:$F,WEAP!$A:$A), IF($I27="","",_xlfn.XLOOKUP($I27,WEAP!$G:$G,WEAP!$A:$A,"")) ) | E27: =IFERROR( _xlfn.XLOOKUP($H27,WEAP!$F:$F,WEAP!$B:$B), IF($I27="","",_xlfn.XLOOKUP($I27,WEAP!$G:$G,WEAP!$B:$B,"")) ) | F27: =IFERROR( _xlfn.XLOOKUP($H27,WEAP!$F:$F,WEAP!$C:$C), IF($I27="","",_xlfn.XLOOKUP($I27,WEAP!$G:$G,WEAP!$C:$C,"")) ) | G27: =IFERROR( _xlfn.XLOOKUP($H27,WEAP!$F:$F,WEAP!$E:$E), IF($I27="","",_xlfn.XLOOKUP($I27,WEAP!$G:$G,WEAP!$E:$E,"")) ) | H27: =IFERROR( _xlfn.LET( _xlpm.txt,TRIM(B27), _xlpm.before,TRIM(_xlfn.TEXTBEFORE(_xlpm.txt,"\",-1)), _xlpm.after,_xlfn.TEXTAFTER(_xlpm.txt,"\"), _xlpm.lastToken,TRIM(_xlfn.TEXTAFTER(_xlpm.before," ",-1)), _xlpm.isReach,LOWER(TRIM(_xlpm.after))="reach", _xlpm.cleaned, IF( ISNUMBER(--_xlpm.lastToken), _xlfn.TEXTBEFORE(_xlpm.before," ",-1) & " \ " & _xlpm.after, _xlpm.txt ), IF(_xlpm.isReach,_xlpm.txt,TRIM(_xlpm.cleaned)) ), B27 ) -> San Luis\SWP\RuleCurveCalc (Thousand AF) | I27: =IFERROR( _xlfn.LET( _xlpm.txt,B27, _xlpm.before,TRIM(_xlfn.TEXTBEFORE(_xlpm.txt,"\")), _xlpm.after,TRIM(_xlfn.TEXTAFTER(_xlpm.txt,"\")), _xlpm.lastToken,TRIM(_xlfn.TEXTAFTER(_xlpm.before," ",-1)), _xlpm.isNum,IFERROR(ISNUMBER(--_xlpm.lastToken),FALSE), IF( OR( LOWER(_xlpm.after)="headflow", LOWER(_xlpm.after)="reach" ), "", IF( _xlpm.isNum, _xlpm.lastToken & " \ " & _xlpm.after, "" ) ) ), "" )
B28: San Luis\SWP\SWPdemfinal\SWP_demprofile (/AF) | C28: SacWAM | D28: =IFERROR( _xlfn.XLOOKUP($H28,WEAP!$F:$F,WEAP!$A:$A), IF($I28="","",_xlfn.XLOOKUP($I28,WEAP!$G:$G,WEAP!$A:$A,"")) ) | E28: =IFERROR( _xlfn.XLOOKUP($H28,WEAP!$F:$F,WEAP!$B:$B), IF($I28="","",_xlfn.XLOOKUP($I28,WEAP!$G:$G,WEAP!$B:$B,"")) ) | F28: =IFERROR( _xlfn.XLOOKUP($H28,WEAP!$F:$F,WEAP!$C:$C), IF($I28="","",_xlfn.XLOOKUP($I28,WEAP!$G:$G,WEAP!$C:$C,"")) ) | G28: =IFERROR( _xlfn.XLOOKUP($H28,WEAP!$F:$F,WEAP!$E:$E), IF($I28="","",_xlfn.XLOOKUP($I28,WEAP!$G:$G,WEAP!$E:$E,"")) ) | H28: =IFERROR( _xlfn.LET( _xlpm.txt,TRIM(B28), _xlpm.before,TRIM(_xlfn.TEXTBEFORE(_xlpm.txt,"\",-1)), _xlpm.after,_xlfn.TEXTAFTER(_xlpm.txt,"\"), _xlpm.lastToken,TRIM(_xlfn.TEXTAFTER(_xlpm.before," ",-1)), _xlpm.isReach,LOWER(TRIM(_xlpm.after))="reach", _xlpm.cleaned, IF( ISNUMBER(--_xlpm.lastToken), _xlfn.TEXTBEFORE(_xlpm.before," ",-1) & " \ " & _xlpm.after, _xlpm.txt ), IF(_xlpm.isReach,_xlpm.txt,TRIM(_xlpm.cleaned)) ), B28 ) -> San Luis\SWP\SWPdemfinal\SWP_demprofile (/AF) | I28: =IFERROR( _xlfn.LET( _xlpm.txt,B28, _xlpm.before,TRIM(_xlfn.TEXTBEFORE(_xlpm.txt,"\")), _xlpm.after,TRIM(_xlfn.TEXTAFTER(_xlpm.txt,"\")), _xlpm.lastToken,TRIM(_xlfn.TEXTAFTER(_xlpm.before," ",-1)), _xlpm.isNum,IFERROR(ISNUMBER(--_xlpm.lastToken),FALSE), IF( OR( LOWER(_xlpm.after)="headflow", LOWER(_xlpm.after)="reach" ), "", IF( _xlpm.isNum, _xlpm.lastToken & " \ " & _xlpm.after, "" ) ) ), "" )
... B36: Folsom Rule Curve | C36: SacWAM | D36: =IFERROR( _xlfn.XLOOKUP($H36,WEAP!$F:$F,WEAP!$A:$A), IF($I36="","",_xlfn.XLOOKUP($I36,WEAP!$G:$G,WEAP!$A:$A,"")) ) | E36: =IFERROR( _xlfn.XLOOKUP($H36,WEAP!$F:$F,WEAP!$B:$B), IF($I36="","",_xlfn.XLOOKUP($I36,WEAP!$G:$G,WEAP!$B:$B,"")) ) | F36: =IFERROR( _xlfn.XLOOKUP($H36,WEAP!$F:$F,WEAP!$C:$C), IF($I36="","",_xlfn.XLOOKUP($I36,WEAP!$G:$G,WEAP!$C:$C,"")) ) | G36: =IFERROR( _xlfn.XLOOKUP($H36,WEAP!$F:$F,WEAP!$E:$E), IF($I36="","",_xlfn.XLOOKUP($I36,WEAP!$G:$G,WEAP!$E:$E,"")) ) | H36: =IFERROR( _xlfn.LET( _xlpm.txt,TRIM(B36), _xlpm.before,TRIM(_xlfn.TEXTBEFORE(_xlpm.txt,"\",-1)), _xlpm.after,_xlfn.TEXTAFTER(_xlpm.txt,"\"), _xlpm.lastToken,TRIM(_xlfn.TEXTAFTER(_xlpm.before," ",-1)), _xlpm.isReach,LOWER(TRIM(_xlpm.after))="reach", _xlpm.cleaned, IF( ISNUMBER(--_xlpm.lastToken), _xlfn.TEXTBEFORE(_xlpm.before," ",-1) & " \ " & _xlpm.after, _xlpm.txt ), IF(_xlpm.isReach,_xlpm.txt,TRIM(_xlpm.cleaned)) ), B36 ) -> Folsom Rule Curve | I36: =IFERROR( _xlfn.LET( _xlpm.txt,B36, _xlpm.before,TRIM(_xlfn.TEXTBEFORE(_xlpm.txt,"\")), _xlpm.after,TRIM(_xlfn.TEXTAFTER(_xlpm.txt,"\")), _xlpm.lastToken,TRIM(_xlfn.TEXTAFTER(_xlpm.before," ",-1)), _xlpm.isNum,IFERROR(ISNUMBER(--_xlpm.lastToken),FALSE), IF( OR( LOWER(_xlpm.after)="headflow", LOWER(_xlpm.after)="reach" ), "", IF( _xlpm.isNum, _xlpm.lastToken & " \ " & _xlpm.after, "" ) ) ), "" )
A37: D_NFA016_ABT002 | B37: Auburn Tunnel 0 \ Headflow | C37: SacWAM | D37: =IFERROR( _xlfn.XLOOKUP($H37,WEAP!$F:$F,WEAP!$A:$A), IF($I37="","",_xlfn.XLOOKUP($I37,WEAP!$G:$G,WEAP!$A:$A,"")) ) -> 8471 | E37: =IFERROR( _xlfn.XLOOKUP($H37,WEAP!$F:$F,WEAP!$B:$B), IF($I37="","",_xlfn.XLOOKUP($I37,WEAP!$G:$G,WEAP!$B:$B,"")) ) -> Auburn Tunnel 0 \ Headflow | F37: =IFERROR( _xlfn.XLOOKUP($H37,WEAP!$F:$F,WEAP!$C:$C), IF($I37="","",_xlfn.XLOOKUP($I37,WEAP!$G:$G,WEAP!$C:$C,"")) ) -> taf | G37: =IFERROR( _xlfn.XLOOKUP($H37,WEAP!$F:$F,WEAP!$E:$E), IF($I37="","",_xlfn.XLOOKUP($I37,WEAP!$G:$G,WEAP!$E:$E,"")) ) -> Streamflow (below node or reach listed) | H37: =IFERROR( _xlfn.LET( _xlpm.txt,TRIM(B37), _xlpm.before,TRIM(_xlfn.TEXTBEFORE(_xlpm.txt,"\",-1)), _xlpm.after,_xlfn.TEXTAFTER(_xlpm.txt,"\"), _xlpm.lastToken,TRIM(_xlfn.TEXTAFTER(_xlpm.before," ",-1)), _xlpm.isReach,LOWER(TRIM(_xlpm.after))="reach", _xlpm.cleaned, IF( ISNUMBER(--_xlpm.lastToken), _xlfn.TEXTBEFORE(_xlpm.before," ",-1) & " \ " & _xlpm.after, _xlpm.txt ), IF(_xlpm.isReach,_xlpm.txt,TRIM(_xlpm.cleaned)) ), B37 ) -> Auburn Tunnel \ Headflow | I37: =IFERROR( _xlfn.LET( _xlpm.txt,B37, _xlpm.before,TRIM(_xlfn.TEXTBEFORE(_xlpm.txt,"\")), _xlpm.after,TRIM(_xlfn.TEXTAFTER(_xlpm.txt,"\")), _xlpm.lastToken,TRIM(_xlfn.TEXTAFTER(_xlpm.before," ",-1)), _xlpm.isNum,IFERROR(ISNUMBER(--_xlpm.lastToken),FALSE), IF( OR( LOWER(_xlpm.after)="headflow", LOWER(_xlpm.after)="reach" ), "", IF( _xlpm.isNum, _xlpm.lastToken & " \ " & _xlpm.after, "" ) ) ), "" )
A38: D_BRR050_BEC000 | B38: Bear River Canal 0 \ Headflow | C38: SacWAM | D38: =IFERROR( _xlfn.XLOOKUP($H38,WEAP!$F:$F,WEAP!$A:$A), IF($I38="","",_xlfn.XLOOKUP($I38,WEAP!$G:$G,WEAP!$A:$A,"")) ) -> 6539 | E38: =IFERROR( _xlfn.XLOOKUP($H38,WEAP!$F:$F,WEAP!$B:$B), IF($I38="","",_xlfn.XLOOKUP($I38,WEAP!$G:$G,WEAP!$B:$B,"")) ) -> Bear River Canal 0 \ Headflow | F38: =IFERROR( _xlfn.XLOOKUP($H38,WEAP!$F:$F,WEAP!$C:$C), IF($I38="","",_xlfn.XLOOKUP($I38,WEAP!$G:$G,WEAP!$C:$C,"")) ) -> taf | G38: =IFERROR( _xlfn.XLOOKUP($H38,WEAP!$F:$F,WEAP!$E:$E), IF($I38="","",_xlfn.XLOOKUP($I38,WEAP!$G:$G,WEAP!$E:$E,"")) ) -> Streamflow (below node or reach listed) | H38: =IFERROR( _xlfn.LET( _xlpm.txt,TRIM(B38), _xlpm.before,TRIM(_xlfn.TEXTBEFORE(_xlpm.txt,"\",-1)), _xlpm.after,_xlfn.TEXTAFTER(_xlpm.txt,"\"), _xlpm.lastToken,TRIM(_xlfn.TEXTAFTER(_xlpm.before," ",-1)), _xlpm.isReach,LOWER(TRIM(_xlpm.after))="reach", _xlpm.cleaned, IF( ISNUMBER(--_xlpm.lastToken), _xlfn.TEXTBEFORE(_xlpm.before," ",-1) & " \ " & _xlpm.after, _xlpm.txt ), IF(_xlpm.isReach,_xlpm.txt,TRIM(_xlpm.cleaned)) ), B38 ) -> Bear River Canal \ Headflow | I38: =IFERROR( _xlfn.LET( _xlpm.txt,B38, _xlpm.before,TRIM(_xlfn.TEXTBEFORE(_xlpm.txt,"\")), _xlpm.after,TRIM(_xlfn.TEXTAFTER(_xlpm.txt,"\")), _xlpm.lastToken,TRIM(_xlfn.TEXTAFTER(_xlpm.before," ",-1)), _xlpm.isNum,IFERROR(ISNUMBER(--_xlpm.lastToken),FALSE), IF( OR( LOWER(_xlpm.after)="headflow", LOWER(_xlpm.after)="reach" ), "", IF( _xlpm.isNum, _xlpm.lastToken & " \ " & _xlpm.after, "" ) ) ), "" )
A39: D_CCS010_BSC000 | B39: Bowman Spaulding Conduit 0 \ Headflow | C39: SacWAM | D39: =IFERROR( _xlfn.XLOOKUP($H39,WEAP!$F:$F,WEAP!$A:$A), IF($I39="","",_xlfn.XLOOKUP($I39,WEAP!$G:$G,WEAP!$A:$A,"")) ) -> 10839 | E39: =IFERROR( _xlfn.XLOOKUP($H39,WEAP!$F:$F,WEAP!$B:$B), IF($I39="","",_xlfn.XLOOKUP($I39,WEAP!$G:$G,WEAP!$B:$B,"")) ) -> Bowman Spaulding Conduit 0 \ Headflow | F39: =IFERROR( _xlfn.XLOOKUP($H39,WEAP!$F:$F,WEAP!$C:$C), IF($I39="","",_xlfn.XLOOKUP($I39,WEAP!$G:$G,WEAP!$C:$C,"")) ) -> taf | G39: =IFERROR( _xlfn.XLOOKUP($H39,WEAP!$F:$F,WEAP!$E:$E), IF($I39="","",_xlfn.XLOOKUP($I39,WEAP!$G:$G,WEAP!$E:$E,"")) ) -> Streamflow (below node or reach listed) | H39: =IFERROR( _xlfn.LET( _xlpm.txt,TRIM(B39), _xlpm.before,TRIM(_xlfn.TEXTBEFORE(_xlpm.txt,"\",-1)), _xlpm.after,_xlfn.TEXTAFTER(_xlpm.txt,"\"), _xlpm.lastToken,TRIM(_xlfn.TEXTAFTER(_xlpm.before," ",-1)), _xlpm.isReach,LOWER(TRIM(_xlpm.after))="reach", _xlpm.cleaned, IF( ISNUMBER(--_xlpm.lastToken), _xlfn.TEXTBEFORE(_xlpm.before," ",-1) & " \ " & _xlpm.after, _xlpm.txt ), IF(_xlpm.isReach,_xlpm.txt,TRIM(_xlpm.cleaned)) ), B39 ) -> Bowman Spaulding Conduit \ Headflow | I39: =IFERROR( _xlfn.LET( _xlpm.txt,B39, _xlpm.before,TRIM(_xlfn.TEXTBEFORE(_xlpm.txt,"\")), _xlpm.after,TRIM(_xlfn.TEXTAFTER(_xlpm.txt,"\")), _xlpm.lastToken,TRIM(_xlfn.TEXTAFTER(_xlpm.before," ",-1)), _xlpm.isNum,IFERROR(ISNUMBER(--_xlpm.lastToken),FALSE), IF( OR( LOWER(_xlpm.after)="headflow", LOWER(_xlpm.after)="reach" ), "", IF( _xlpm.isNum, _xlpm.lastToken & " \ " & _xlpm.after, "" ) ) ), "" )
A40: D_BSH003_CMN005 | B40: Brush Creek Tunnel 0 \ Headflow | C40: SacWAM | D40: =IFERROR( _xlfn.XLOOKUP($H40,WEAP!$F:$F,WEAP!$A:$A), IF($I40="","",_xlfn.XLOOKUP($I40,WEAP!$G:$G,WEAP!$A:$A,"")) ) -> 13984 | E40: =IFERROR( _xlfn.XLOOKUP($H40,WEAP!$F:$F,WEAP!$B:$B), IF($I40="","",_xlfn.XLOOKUP($I40,WEAP!$G:$G,WEAP!$B:$B,"")) ) -> Brush Creek Tunnel 0 \ Headflow | F40: =IFERROR( _xlfn.XLOOKUP($H40,WEAP!$F:$F,WEAP!$C:$C), IF($I40="","",_xlfn.XLOOKUP($I40,WEAP!$G:$G,WEAP!$C:$C,"")) ) -> taf | G40: =IFERROR( _xlfn.XLOOKUP($H40,WEAP!$F:$F,WEAP!$E:$E), IF($I40="","",_xlfn.XLOOKUP($I40,WEAP!$G:$G,WEAP!$E:$E,"")) ) -> Streamflow (below node or reach listed) | H40: =IFERROR( _xlfn.LET( _xlpm.txt,TRIM(B40), _xlpm.before,TRIM(_xlfn.TEXTBEFORE(_xlpm.txt,"\",-1)), _xlpm.after,_xlfn.TEXTAFTER(_xlpm.txt,"\"), _xlpm.lastToken,TRIM(_xlfn.TEXTAFTER(_xlpm.before," ",-1)), _xlpm.isReach,LOWER(TRIM(_xlpm.after))="reach", _xlpm.cleaned, IF( ISNUMBER(--_xlpm.lastToken), _xlfn.TEXTBEFORE(_xlpm.before," ",-1) & " \ " & _xlpm.after, _xlpm.txt ), IF(_xlpm.isReach,_xlpm.txt,TRIM(_xlpm.cleaned)) ), B40 ) -> Brush Creek Tunnel \ Headflow | I40: =IFERROR( _xlfn.LET( _xlpm.txt,B40, _xlpm.before,TRIM(_xlfn.TEXTBEFORE(_xlpm.txt,"\")), _xlpm.after,TRIM(_xlfn.TEXTAFTER(_xlpm.txt,"\")), _xlpm.lastToken,TRIM(_xlfn.TEXTAFTER(_xlpm.before," ",-1)), _xlpm.isNum,IFERROR(ISNUMBER(--_xlpm.lastToken),FALSE), IF( OR( LOWER(_xlpm.after)="headflow", LOWER(_xlpm.after)="reach" ), "", IF( _xlpm.isNum, _xlpm.lastToken & " \ " & _xlpm.after, "" ) ) ), "" )
A41: D_LRR003_BLT000 | B41: Buck Loon Tunnel 0 \ Headflow | C41: SacWAM | D41: =IFERROR( _xlfn.XLOOKUP($H41,WEAP!$F:$F,WEAP!$A:$A), IF($I41="","",_xlfn.XLOOKUP($I41,WEAP!$G:$G,WEAP!$A:$A,"")) ) -> 11032 | E41: =IFERROR( _xlfn.XLOOKUP($H41,WEAP!$F:$F,WEAP!$B:$B), IF($I41="","",_xlfn.XLOOKUP($I41,WEAP!$G:$G,WEAP!$B:$B,"")) ) -> Buck Loon Tunnel 0 \ Headflow | F41: =IFERROR( _xlfn.XLOOKUP($H41,WEAP!$F:$F,WEAP!$C:$C), IF($I41="","",_xlfn.XLOOKUP($I41,WEAP!$G:$G,WEAP!$C:$C,"")) ) -> taf | G41: =IFERROR( _xlfn.XLOOKUP($H41,WEAP!$F:$F,WEAP!$E:$E), IF($I41="","",_xlfn.XLOOKUP($I41,WEAP!$G:$G,WEAP!$E:$E,"")) ) -> Streamflow (below node or reach listed) | H41: =IFERROR( _xlfn.LET( _xlpm.txt,TRIM(B41), _xlpm.before,TRIM(_xlfn.TEXTBEFORE(_xlpm.txt,"\",-1)), _xlpm.after,_xlfn.TEXTAFTER(_xlpm.txt,"\"), _xlpm.lastToken,TRIM(_xlfn.TEXTAFTER(_xlpm.before," ",-1)), _xlpm.isReach,LOWER(TRIM(_xlpm.after))="reach", _xlpm.cleaned, IF( ISNUMBER(--_xlpm.lastToken), _xlfn.TEXTBEFORE(_xlpm.before," ",-1) & " \ " & _xlpm.after, _xlpm.txt ), IF(_xlpm.isReach,_xlpm.txt,TRIM(_xlpm.cleaned)) ), B41 ) -> Buck Loon Tunnel \ Headflow | I41: =IFERROR( _xlfn.LET( _xlpm.txt,B41, _xlpm.before,TRIM(_xlfn.TEXTBEFORE(_xlpm.txt,"\")), _xlpm.after,TRIM(_xlfn.TEXTAFTER(_xlpm.txt,"\")), _xlpm.lastToken,TRIM(_xlfn.TEXTAFTER(_xlpm.before," ",-1)), _xlpm.isNum,IFERROR(ISNUMBER(--_xlpm.lastToken),FALSE), IF( OR( LOWER(_xlpm.after)="headflow", LOWER(_xlpm.after)="reach" ), "", IF( _xlpm.isNum, _xlpm.lastToken & " \ " & _xlpm.after, "" ) ) ), "" )
A42: C_CAA003 | B42: California Aqueduct 0 \ Headflow | C42: SacWAM | D42: =IFERROR( _xlfn.XLOOKUP($H42,WEAP!$F:$F,WEAP!$A:$A), IF($I42="","",_xlfn.XLOOKUP($I42,WEAP!$G:$G,WEAP!$A:$A,"")) ) -> 6638 | E42: =IFERROR( _xlfn.XLOOKUP($H42,WEAP!$F:$F,WEAP!$B:$B), IF($I42="","",_xlfn.XLOOKUP($I42,WEAP!$G:$G,WEAP!$B:$B,"")) ) -> California Aqueduct 0 \ Headflow | F42: =IFERROR( _xlfn.XLOOKUP($H42,WEAP!$F:$F,WEAP!$C:$C), IF($I42="","",_xlfn.XLOOKUP($I42,WEAP!$G:$G,WEAP!$C:$C,"")) ) -> taf | G42: =IFERROR( _xlfn.XLOOKUP($H42,WEAP!$F:$F,WEAP!$E:$E), IF($I42="","",_xlfn.XLOOKUP($I42,WEAP!$G:$G,WEAP!$E:$E,"")) ) -> Streamflow (below node or reach listed) | H42: =IFERROR( _xlfn.LET( _xlpm.txt,TRIM(B42), _xlpm.before,TRIM(_xlfn.TEXTBEFORE(_xlpm.txt,"\",-1)), _xlpm.after,_xlfn.TEXTAFTER(_xlpm.txt,"\"), _xlpm.lastToken,TRIM(_xlfn.TEXTAFTER(_xlpm.before," ",-1)), _xlpm.isReach,LOWER(TRIM(_xlpm.after))="reach", _xlpm.cleaned, IF( ISNUMBER(--_xlpm.lastToken), _xlfn.TEXTBEFORE(_xlpm.before," ",-1) & " \ " & _xlpm.after, _xlpm.txt ), IF(_xlpm.isReach,_xlpm.txt,TRIM(_xlpm.cleaned)) ), B42 ) -> California Aqueduct \ Headflow | I42: =IFERROR( _xlfn.LET( _xlpm.txt,B42, _xlpm.before,TRIM(_xlfn.TEXTBEFORE(_xlpm.txt,"\")), _xlpm.after,TRIM(_xlfn.TEXTAFTER(_xlpm.txt,"\")), _xlpm.lastToken,TRIM(_xlfn.TEXTAFTER(_xlpm.before," ",-1)), _xlpm.isNum,IFERROR(ISNUMBER(--_xlpm.lastToken),FALSE), IF( OR( LOWER(_xlpm.after)="headflow", LOWER(_xlpm.after)="reach" ), "", IF( _xlpm.isNum, _xlpm.lastToken & " \ " & _xlpm.after, "" ) ) ), "" )
A43: D_JNKSN_ELDID | B43: Jenkinson Lake Camino Conduit 0 \ Headflow | C43: SacWAM | D43: =IFERROR( _xlfn.XLOOKUP($H43,WEAP!$F:$F,WEAP!$A:$A), IF($I43="","",_xlfn.XLOOKUP($I43,WEAP!$G:$G,WEAP!$A:$A,"")) ) -> 14674 | E43: =IFERROR( _xlfn.XLOOKUP($H43,WEAP!$F:$F,WEAP!$B:$B), IF($I43="","",_xlfn.XLOOKUP($I43,WEAP!$G:$G,WEAP!$B:$B,"")) ) -> Jenkinson Lake Camino Conduit 0 \ Headflow | F43: =IFERROR( _xlfn.XLOOKUP($H43,WEAP!$F:$F,WEAP!$C:$C), IF($I43="","",_xlfn.XLOOKUP($I43,WEAP!$G:$G,WEAP!$C:$C,"")) ) -> taf | G43: =IFERROR( _xlfn.XLOOKUP($H43,WEAP!$F:$F,WEAP!$E:$E), IF($I43="","",_xlfn.XLOOKUP($I43,WEAP!$G:$G,WEAP!$E:$E,"")) ) -> Streamflow (below node or reach listed) | H43: =IFERROR( _xlfn.LET( _xlpm.txt,TRIM(B43), _xlpm.before,TRIM(_xlfn.TEXTBEFORE(_xlpm.txt,"\",-1)), _xlpm.after,_xlfn.TEXTAFTER(_xlpm.txt,"\"), _xlpm.lastToken,TRIM(_xlfn.TEXTAFTER(_xlpm.before," ",-1)), _xlpm.isReach,LOWER(TRIM(_xlpm.after))="reach", _xlpm.cleaned, IF( ISNUMBER(--_xlpm.lastToken), _xlfn.TEXTBEFORE(_xlpm.before," ",-1) & " \ " & _xlpm.after, _xlpm.txt ), IF(_xlpm.isReach,_xlpm.txt,TRIM(_xlpm.cleaned)) ), B43 ) -> Jenkinson Lake Camino Conduit \ Headflow | I43: =IFERROR( _xlfn.LET( _xlpm.txt,B43, _xlpm.before,TRIM(_xlfn.TEXTBEFORE(_xlpm.txt,"\")), _xlpm.after,TRIM(_xlfn.TEXTAFTER(_xlpm.txt,"\")), _xlpm.lastToken,TRIM(_xlfn.TEXTAFTER(_xlpm.before," ",-1)), _xlpm.isNum,IFERROR(ISNUMBER(--_xlpm.lastToken),FALSE), IF( OR( LOWER(_xlpm.after)="headflow", LOWER(_xlpm.after)="reach" ), "", IF( _xlpm.isNum, _xlpm.lastToken & " \ " & _xlpm.after, "" ) ) ), "" )
